Workbook

Sheet Supplemental Sheet
C3: Technical Experimentation Event Supplemental Information Sheet
F4: Version MAY2025. All other forms are obsolete
C6: Failure to complete this sheet, in its ENTIRETY, may result in non-consideration by the government for this event.
C7: Any box that is not applicable to your experiment must be marked with, n/a or No
C8: Version MAY2025 | D8: All previous versions are obsolete. Older versions submitted will be rejected.
C9: DO NOT USE THIS FORM FOR ANY OTHER TE, IT WILL BE REJECTED.
C10: If you have any questions or issues completing this form, please email: | E10: Tech_Exp@socom.mil
C12: Experiment ID: Gov Use only
C14: * 1. Experiment Name: (DO NOT use the Event name)
C16: Brief Experiment Name: (DO NOT use the Event name)
C18: * 2. Event Number: | D18: TE25-3
C20: * 3. Company Name:
C22: 4. Cage Code: If none, mark as n/a
C24: 5. DUNS Number: If none, mark as n/a
C26: * 6. Are you a small business?: | D26: Select One
C28: * 7. Principle Investigator/PI:
C30: * 8. PI Telephone Number: (Only use a number that will answered)
C32: * 9. PI Email Address: (Only use an email that will be answered)
C34: 10. USSOCOM/SOF POC (If Applicable):
C36: 11. USSOCOM/SOF POC Telephone Number: (If Applicable)
C38: 12. USSOCOM/SOF POC Email Address: (If Applicable)
C40: * 13. Capability Area of Interest (Select One): | D40: Select the Best One
C42: * 14. Technology Readiness Level (Select One): | D42: Select One
C44: * 15. Technology CONOP: A Concept of Operations (CONOPS) is a document that describes a proposed system or operation, outlining its characteristics and how it will be used. ensuring that all stakeholders have a shared understanding of its intended purpose, functionality, and operational context. (1270 character limit) Double click the area below to add text.
C47: *16. Experiment Objectives: What is it you intend to prove? Objectives should be clearly stated, using specific verbs that describe the actions you will take, such as "to measure," "to analyze," "to determine," or "to test". (1200 character limit) Double click the area below to add text.
C50: * 17. Do you prefer an inside and/or Outside Space: Please specify limiting environmental factors (255 character limit) Double click the area below to add text.
C53: * 18 Will you bring an Unmanned Aerial Systems/UAS: | D53: Select One | E53: If no is selected before moving to next section mark n/a for 18a - 18g
C54: 18a. UAS Make, Model and Quantity: | E54: UAS Make | F54: Model | G54: Qty
G55: Select
G56: Select
G57: Select
C58: 18b. Do you have a current Cyber Vulnerability Assessment? | D58: Select One
C59: 18c. Is your platform a Program of Record (POR)? | D59: Select One
C60: 18d. Is there a COA for your platform at the event site? | D60: Select One
C61: 18e. Do you hold a current AWR, IFC, or ASR for the event site? | D61: Select One
C62: 18f. Do you hold a current 107 License | D62: Select One
C63: 18g. Do you have current Liability Insurance | D63: Select One
C65: 19. Responsibilities: - Participant Names/Responsibilities. Double click the area below to add text.
C68: 20. Safety: - Other potential safety issues, e.g. explosives, pyrotechnics, hazardous chemical substances, or other occupational hazards. If none mark n/a. Double click the area below to add text.
C71: *21. Live fire: -Does your experiment include live fire/kinetic/energetic operations? | D71: Select One | E71: If no is selected before moving to next section mark n/a for 21a - 21a-4
...

Sheet SuppTable
A1: Exp ID | B1: Experiment Name | C1: Brief Experiment Name | D1: Event Number | E1: Company Name | F1: Cage Code | G1: DUNS Number | H1: Are you a small business | I1: Principle Investigator/PI | J1: PI Telephone Number | K1: PI Email Address | L1: USSOCOM/SOF POC (If Applicable) | M1: USSOCOM/SOF POC Telephone Number: (If Applicable) | N1: USSOCOM/SOF POC Email Address: (If Applicable) | O1: Capability Area of Interest: | P1: Technology Readiness Level | Q1: Technology CONOP: Provide a brief description of your technology, what it is, and what it does. | R1: Experiment Objectives: What is it you intend to prove? | S1: Do you prefer an inside and/or Outside Space: | T1: Will you bring an Unmanned Aerial Systems/UAS | U1: UAS Make | V1: Model | W1: Quantity | X1: UAS Make | Y1: Model3 | Z1: Quantity3 | AA1: UAS Make2 | AB1: Model2 | AC1: Quantity2 | AD1: Do you have a current Cyber Vulnerability Assessment? | AE1: Is your platform a Program of Record (POR)? | AF1: Is there a COA for your platform at the event site? | AG1: Do you hold a current AWR, IFC, or ASR for the event site? | AH1: Do you hold a current 107 License? | AI1: Do you have current Liability Insurance? | AJ1: Responsibilities: - Participant Names/Responsibilities. | AK1: Safety: - Other potential safety issues, e.g. explosives, pyrotechnics, hazardous chemical substances, or other occupational hazards. | AL1: Live fire: -Does your experiment include live fire/kinetic/energetic operations? | AM1: Caliber & Type | AN1: Qty of Rounds | AO1: Type of Explosives | AP1: Qty of Explosives | AQ1: Laser: - Does your experiment involve the use of lasers, to include eye safe lasers? | AR1: Laser Class: | AS1: Laser wavelength: (in nanometers) | AT1: Output power in watts | AU1: Mode of operation | AV1: Has your laser/device received a military service verification/validation? | AW1: Beam diameter (FWHM) at the output | AX1: Horizontal divergence, in degrees | AY1: Vertical divergence, in degrees | AZ1: Vehicles: - Does your experiment require vehicles, ATVs, trucks, etc. as part of the actual experiment? | BA1: Vehicle Use: List vehicle type and use. (250 Character Limit) | BB1: Night Operations: -Does your experiment require operating during the hours of darkness? | BC1: Communication Frequency: Are frequencies required: | BD1: Frequency Band: | BE1: Antenna type: | BF1: Power transmitted: (Specify watts or dBm) | BG1: FCC ID#: (If none, mark as n/a) | BH1: What is the weight of your technology solution? Please specify units. If this is not applicable, type in N/A. | BI1: What are the physical dimensions of your technology solution? - If this is not applicable, type in N/A. | BJ1: Power: - Is there a power requirement for your technology solution? | BK1: Total Voltage: | BL1: Total Amps: | BM1: Remote Site: - If a remote site is needed (e.g. experiment cannot take place at the main building), what support is required? | BN1: Remote Power: - Is remote power required? | BO1: List required power | BP1: Publish: - Do you anticipate publishing the results of your experiment? | BQ1: Publish Location: (which publication?) | BR1: International Traffic in Arms (ITAR) or Export Administration Regulations (EAR):
A2: ='Supplemental Sheet'!D12 -> 0 | B2: ='Supplemental Sheet'!E14 -> 0 | C2: ='Supplemental Sheet'!E16 -> 0 | D2: ='Supplemental Sheet'!D18 -> TE25-3 | E2: ='Supplemental Sheet'!E20 -> 0 | F2: ='Supplemental Sheet'!E22 -> 0 | G2: ='Supplemental Sheet'!E24 -> 0 | H2: ='Supplemental Sheet'!D26 -> Select One | I2: ='Supplemental Sheet'!E28 -> 0 | J2: ='Supplemental Sheet'!E30 -> 0 | K2: ='Supplemental Sheet'!E32 -> 0 | L2: ='Supplemental Sheet'!E34 -> 0 | M2: ='Supplemental Sheet'!E36 -> 0 | N2: ='Supplemental Sheet'!E38 -> 0 | O2: ='Supplemental Sheet'!D40 -> Select the Best One | P2: ='Supplemental Sheet'!D42 -> Select One | Q2: ='Supplemental Sheet'!C45 -> 0 | R2: ='Supplemental Sheet'!C48 -> 0 | S2: ='Supplemental Sheet'!C51 -> 0 | T2: ='Supplemental Sheet'!D53 -> Select One | U2: ='Supplemental Sheet'!E55 -> 0 | V2: ='Supplemental Sheet'!F55 -> 0 | W2: ='Supplemental Sheet'!G55 -> Select | X2: ='Supplemental Sheet'!E56 -> 0 | Y2: ='Supplemental Sheet'!F56 -> 0 | Z2: ='Supplemental Sheet'!G56 -> Select | AA2: ='Supplemental Sheet'!E57 -> 0 | AB2: ='Supplemental Sheet'!F57 -> 0 | AC2: ='Supplemental Sheet'!G57 -> Select | AD2: ='Supplemental Sheet'!D58 -> Select One | AE2: ='Supplemental Sheet'!D59 -> Select One | AF2: ='Supplemental Sheet'!D60 -> Select One | AG2: ='Supplemental Sheet'!D61 -> Select One | AH2: ='Supplemental Sheet'!F60 -> 0 | AI2: ='Supplemental Sheet'!F61 -> 0 | AJ2: ='Supplemental Sheet'!D66 -> 0 | AK2: ='Supplemental Sheet'!D69 -> 0 | AL2: ='Supplemental Sheet'!D71 -> Select One | AM2: =SUM('Supplemental Sheet'!D73) -> 0 | AN2: =SUM('Supplemental Sheet'!E73) -> 0 | AO2: =SUM('Supplemental Sheet'!F73) -> 0 | AP2: =SUM('Supplemental Sheet'!G73) -> 0 | AQ2: ='Supplemental Sheet'!D78 -> Select One | AR2: ='Supplemental Sheet'!D79 -> Select One | AS2: ='Supplemental Sheet'!D80 -> 0 | AT2: ='Supplemental Sheet'!D81 -> 0 | AU2: ='Supplemental Sheet'!D82 -> 0 | AV2: ='Supplemental Sheet'!F79 -> Select One | AW2: ='Supplemental Sheet'!F80 -> 0 | AX2: ='Supplemental Sheet'!F81 -> 0 | AY2: ='Supplemental Sheet'!F82 -> 0 | AZ2: ='Supplemental Sheet'!D85 -> Select One | BA2: ='Supplemental Sheet'!D86 -> 0 | BB2: ='Supplemental Sheet'!D88 -> Select One | BC2: ='Supplemental Sheet'!D90 -> Select One | BD2: ='Supplemental Sheet'!D91 -> 0 | BE2: ='Supplemental Sheet'!D92 -> 0 | BF2: ='Supplemental Sheet'!D93 -> 0 | BG2: ='Supplemental Sheet'!D94 -> 0 | BH2: ='Supplemental Sheet'!D98 -> 0 | BI2: ='Supplemental Sheet'!D98 -> 0 | BJ2: ='Supplemental Sheet'!D100 -> Select One | BK2: ='Supplemental Sheet'!D102 -> 0 | BL2: ='Supplemental Sheet'!D103 -> 0 | BM2: ='Supplemental Sheet'!D105 -> 0 | BN2: ='Supplemental Sheet'!D107 -> Select One | BO2: ='Supplemental Sheet'!D108 -> 0 | BP2: ='Supplemental Sheet'!D110 -> Select One | BQ2: ='Supplemental Sheet'!D111 -> 0 | BR2: ='Supplemental Sheet'!D113 -> Select One

Sheet AddUasExpTable
A1: Exp ID | B1: 1. Exp Name | C1: Brief Experiment Name | D1: 2. Event Number | E1: 3. Company Name | F1: 14a-2: UAS Make | G1: 14a-2: Model | H1: 14a-2: Quantity | I1: 14b. Do you have a current Cyber Vulnerability Assessment? | J1: 14c. Is your platform a Program of Record (POR)? | K1: 14d. Is there a COA for your platform at the event site? | L1: 14e. Do you hold a current AWR, IFC, or ASR for the event site? | M1: 15. Responsibilities: - Participant Names/Responsibilities. | N1: 16. Safety: - Other potential safety issues, e.g. explosives, pyrotechnics, hazardous chemical substances, or other occupational hazards. | O1: *17. Live fire: -Does your experiment include live fire/kinetic/energetic operations? | P1: 17.a Caliber & Type | Q1: 17.a Qty of Rounds | R1: 17.a type of Explosives | S1: 17.a Qty of Explosives
A2: ='Supplemental Sheet'!D12 -> 0 | B2: ='Supplemental Sheet'!E14 -> 0 | C2: ='Supplemental Sheet'!E16 -> 0 | D2: ='Supplemental Sheet'!D18 -> TE25-3 | E2: ='Supplemental Sheet'!E20 -> 0 | F2: ='Supplemental Sheet'!E56 -> 0 | G2: ='Supplemental Sheet'!F55 -> 0 | H2: ='Supplemental Sheet'!G55 -> Select | I2: ='Supplemental Sheet'!D58 -> Select One | J2: ='Supplemental Sheet'!D59 -> Select One | K2: ='Supplemental Sheet'!D60 -> Select One | L2: ='Supplemental Sheet'!D61 -> Select One | M2: ='Supplemental Sheet'!D66 -> 0 | N2: ='Supplemental Sheet'!D69 -> 0 | O2: ='Supplemental Sheet'!D71 -> Select One | P2: ='Supplemental Sheet'!E74 -> 0 | Q2: ='Supplemental Sheet'!E73 -> 0 | R2: ='Supplemental Sheet'!F73 -> 0 | S2: ='Supplemental Sheet'!G73 -> 0
A3: ='Supplemental Sheet'!D12 -> 0 | B3: ='Supplemental Sheet'!E14 -> 0 | C3: ='Supplemental Sheet'!E16 -> 0 | D3: ='Supplemental Sheet'!D18 -> TE25-3 | E3: ='Supplemental Sheet'!E20 -> 0 | F3: ='Supplemental Sheet'!E57 -> 0 | G3: ='Supplemental Sheet'!F56 -> 0 | H3: ='Supplemental Sheet'!G56 -> Select | I3: ='Supplemental Sheet'!D58 -> Select One | J3: ='Supplemental Sheet'!D59 -> Select One | K3: ='Supplemental Sheet'!D60 -> Select One | L3: ='Supplemental Sheet'!D61 -> Select One | M3: ='Supplemental Sheet'!D66 -> 0 | N3: ='Supplemental Sheet'!D69 -> 0 | O3: ='Supplemental Sheet'!D71 -> Select One | P3: ='Supplemental Sheet'!E75 -> 0 | Q3: ='Supplemental Sheet'!E74 -> 0 | R3: ='Supplemental Sheet'!F74 -> 0 | S3: ='Supplemental Sheet'!G74 -> 0
A4: ='Supplemental Sheet'!D12 -> 0 | B4: ='Supplemental Sheet'!E14 -> 0 | C4: ='Supplemental Sheet'!E16 -> 0 | D4: ='Supplemental Sheet'!D18 -> TE25-3 | E4: ='Supplemental Sheet'!E20 -> 0 | F4: ='Supplemental Sheet'!E58 -> 0 | G4: ='Supplemental Sheet'!F57 -> 0 | H4: ='Supplemental Sheet'!G57 -> Select | I4: ='Supplemental Sheet'!D58 -> Select One | J4: ='Supplemental Sheet'!D59 -> Select One | K4: ='Supplemental Sheet'!D60 -> Select One | L4: ='Supplemental Sheet'!D61 -> Select One | M4: ='Supplemental Sheet'!D66 -> 0 | N4: ='Supplemental Sheet'!D69 -> 0 | O4: ='Supplemental Sheet'!D71 -> Select One | P4: ='Supplemental Sheet'!E76 -> 0 | Q4: ='Supplemental Sheet'!E75 -> 0 | R4: ='Supplemental Sheet'!F75 -> 0 | S4: ='Supplemental Sheet'!G75 -> 0

Sheet Sheet3
A1: 14. UAS | B1: *6. Are you a small business?: | C1: *2. Event Number: | D1: Technology Readiness Level | E1: Capability Area of Interest | F1: *14a. Qty | G1: *21: Live fire: | H1: 22. Laser | I1: 22a:. Laser Class: | J1: 22b:. Mode of operation | K1: 19. Vehicles | L1: 21. Communication Frequency | M1: 23. Power | N1: 25. remote Power | O1: 26a. Publishing | P1: 27. ITAR
A2: Select One | B2: Select One | C2: Select One | D2: Select One | E2: Select the Best One | F2: Select | G2: Select One | H2: Select One | I2: Select One | J2: Select One | K2: Select One | L2: Select One | M2: Select One | N2: Select One | O2: Select One | P2: Select One
A3: NO, Mark all sub categoris as n/a then Proceed to 19 | B3: n/a | C3: TE25-3 | D3: TRL 1 – Basic Principles Observed and Reported | E3: 4.1 Modular, National Defense Authorization Act (NDAA) compliant, low Size, Weight, and Power-Cost (SWaP-C) UxS Solutions. | F3: n/a | G3: YES, Complete All of 21 and 21a. | H3: YES, Proceed to 22a | I3: Class 1 | J3: Pulsed Wave | K3: YES, Proceed to 23a | L3: YES, proceed to 25a | M3: YES, Proceed to 27a | N3: YES, Proceed to 29a | O3: YES, Complete all of 30 | P3: NO
A4: YES, Proceed to 18a | B4: NO | D4: TRL 2 – Technology Concept and/or Application Formulated | E4: 4.2 Multi-Modal, Multi-Domain Unmanned Systems and capabilities | F4: 1 | G4: NO, Mark all sub categoris as n/a then Proceed to 22 | H4: NO, Mark all sub categoris as n/a then Proceed to 23 | I4: Class 1M | J4: Continuous Wave | K4: NO, Mark all sub categoris as n/a then Proceed to 24 | L4: NO, Mark all sub categoris as n/a thenproceed to 26 | M4: NO, Mark all sub categoris as n/a then Proceed to 28 | N4: NO, Mark all sub categoris as n/a then, Proceed to 30 | O4: NO, Mark all sub categoris as n/a then, Proceed to 31 | P4: EAR
B5: YES | D5: TRL 3 – Analytical and Experimental Critical Function and/or Characteristic Proof-of-Concept | E5: 4.3 Edge processing capacity | F5: 2 | I5: Class 2 | P5: ITAR
D6: TRL 4 – Component and/or Validation in Laboratory Environment | E6: 4.4 Heterogeneous teaming and UAS Swarming capabilities. | F6: 3 | I6: Class 2M
D7: TRL 5 – Component and/or Validation in a Relevant Environment | E7: 4.5 Autonomous operations for GPS-denied environments | F7: 4 | I7: Class 3R
D8: TRL 6 – System/Subsystem Model or Prototype Demo in a Relevant Environment (Ground or Space) | E8: 4.6 First Person View (FPV) UxS and components from non-covered foreign countries or US manufacturers only. | F8: 5 | I8: Class 3B
D9: TRL 7 – System Prototype Demonstrated in an Actual Environment | E9: 4.7 Data Transport | F9: 6 | I9: Class 4
D10: TRL 8 – Actual System Completed and “Qualified” Through Test and Demonstration | E10: 4.8 Voice and Data Processing | F10: 7
D11: TRL 9 – Actual System Proven Through Successful Mission Operations | E11: 4.9 UxS Human-Machine Interface capabilities | F11: 8
E12: 4.10 Unmanned Aerial Systems (UAS) capabilities | F12: 9
E13: 4.11 Unmanned Ground Vehicles (UGV) | F13: 10
E14: 4.12 Counter UxS capabilities
E15: 4.13 Counter Ubiquitous Technologic Surveillance (C-UTS) Technologies
E16: 4.14 Blue force awareness technology
E17: 4.15 High Altitude Sensor Payloads
E18: 4.16 High Altitude platforms
E19: 4.17 Light-weight Air Launched Glide Munition
E20: 4.18 Decoy Payload for UAS or high-altitude platforms
