Workbook
Name Common: #REF!
Name Consum: #REF!
Name EngRate: #REF!
Name GARate: #REF!
Name GrossProfit: #REF!
Name MatHandle: #REF!
Name Risk: #REF!
Name ShopRate: #REF!

Sheet Cost Format C_CLIN Summary
A1: Common Armament Tester - Fighters (CAT-F) Excel Cost Model (RFP Attachment XX)
A2: "Offeror shall enter data in yellow highlighted fields only"
A4: Solicitation Number:
A5: Enter Offeror's Business Name:
A6: Enter Offeror's CAGE code:
A8: Basic Period (12 months)
A9: CLIN | B9: Contract Type | C9: Description | D9: QTY | E9: Unit | F9: Cost | G9: COM | H9: Fee | I9: Unit Price | J9: Extended Price
A10: 0001 | B10: CPFF | C10: F-16 O-Level Handheld/Pre-load Tester Prototype design and digital development | D10: 1 | E10: LO | F10: ='Cost Format A_CLIN X001'!E68 -> 0 | G10: ='Cost Format A_CLIN X001'!E69 -> 0 | H10: ='Cost Format A_CLIN X001'!E70 -> 0 | I10: =+SUM(F10:H10) -> 0 | J10: =+D10*I10 -> 0
A11: 0002 | B11: CPFF | C11: F-15 O-Level Handheld/Pre-load Tester Prototype design and digital development | D11: 1 | E11: LO | F11: ='Cost Format A_CLIN X002'!E68 -> 0 | G11: ='Cost Format A_CLIN X002'!E69 -> 0 | H11: ='Cost Format A_CLIN X002'!E70 -> 0 | I11: =+SUM(F11:H11) -> 0 | J11: =+D11*I11 -> 0
A12: 0003 | B12: CPFF | C12: A-10 O-Level Handheld/Pre-load Tester Prototype design and digital development | D12: 1 | E12: LO | F12: ='Cost Format A_CLIN X003'!E68 -> 0 | G12: ='Cost Format A_CLIN X003'!E69 -> 0 | H12: ='Cost Format A_CLIN X003'!E70 -> 0 | I12: 0 | J12: =+D12*I12 -> 0
A13: 0004 | B13: CPFF | C13: F-16 I-Level Fault Isolation Tester design and digital development | D13: 1 | E13: LO | F13: ='Cost Format A_CLIN X004'!E68 -> 0 | G13: ='Cost Format A_CLIN X004'!E69 -> 0 | H13: ='Cost Format A_CLIN X004'!E70 -> 0 | I13: 0 | J13: =+D13*I13 -> 0
A14: 0005 | B14: CPFF | C14: F-15 I-Level Fault Isolation Tester design and digital development | D14: 1 | E14: LO | F14: ='Cost Format A_CLIN X005'!E68 -> 0 | G14: ='Cost Format A_CLIN X005'!E69 -> 0 | H14: ='Cost Format A_CLIN X005'!E70 -> 0 | I14: 0 | J14: =+D14*I14 -> 0
A15: 0006 | B15: CPFF | C15: A-10 I-Level Fault Isolation Tester design and digital development | D15: 1 | E15: LO | F15: ='Cost Format A_CLIN X006'!E68 -> 0 | G15: ='Cost Format A_CLIN X006'!E69 -> 0 | H15: ='Cost Format A_CLIN X006'!E70 -> 0 | I15: =+SUM(F15:H15) -> 0 | J15: =+D15*I15 -> 0
A16: 0007 | B16: FFP | C16: Deliver F-16 O-Level Handheld Tester Prototype | D16: 4 | E16: EA | I16: ='FFP CLINs'!D9 -> 0 | J16: =+D16*I16 -> 0
A17: 0008 | B17: FFP | C17: Deliver F-15 O-Level Handheld Tester Prototype | D17: 4 | E17: EA | I17: ='FFP CLINs'!D13 -> 0 | J17: =+D17*I17 -> 0
A18: 0009 | B18: FFP | C18: Deliver A-10 O-Level Handheld Tester Prototype | D18: 4 | E18: EA | I18: ='FFP CLINs'!D17 -> 0 | J18: =+D18*I18 -> 0
A19: 0010 | B19: FFP | C19: Deliver F-16 I-Level Fault Isolation Tester digital design | D19: 1 | E19: LO | I19: ='FFP CLINs'!D21 -> 0 | J19: =+D19*I19 -> 0
A20: 0011 | B20: FFP | C20: Deliver F-15 I-Level Fault Isolation Tester digital design | D20: 1 | E20: LO | I20: ='FFP CLINs'!D25 -> 0 | J20: =+D20*I20 -> 0
A21: 0012 | B21: FFP | C21: Deliver A-10 I-Level Fault Isolation Tester digital design | D21: 1 | E21: LO | I21: ='FFP CLINs'!D29 -> 0 | J21: =+D21*I21 -> 0
A22: 0013 | B22: FFP | C22: Program Management | D22: 1 | E22: LO | I22: ='FFP CLINs'!D33 -> 0 | J22: =+D22*I22 -> 0
A23: 0014 | B23: CPFF | C23: Design Demonstration (Labor- Not Travel) | D23: 1 | E23: LO | F23: ='Cost Format A_CLIN 1014'!E68 -> 0 | G23: ='Cost Format A_CLIN 1014'!E69 -> 0 | H23: ='Cost Format A_CLIN 1014'!E70 -> 0 | I23: =+SUM(F23:H23) -> 0 | J23: =+D23*I23 -> 0
A24: 0015 | B24: CRNF | C24: Travel | D24: 1 | E24: LO | F24: ='Cost Format A_Travel CLINs'!E25 -> 0 | G24: ='Cost Format A_Travel CLINs'!E26 -> 0 | I24: =+SUM(F24:H24) -> 0 | J24: =+D24*I24 -> 0
A25: 0016 | B25: FFP | C25: Government Data Rights | D25: 1 | E25: LO | I25: ='FFP CLINs'!D37 -> 0 | J25: =+D25*I25 -> 0
A26: 0017 | B26: NSP | C26: CDRLs (Data) | D26: 1 | E26: LO | F26: NSP
A27: Total Extended Price - Basic Period | J27: =SUM(J10:J15) -> 0
A29: Option Period I (12 months)
A30: CLIN | B30: Contract Type | C30: Description | D30: QTY | E30: Unit | F30: Cost | G30: COM | H30: Fee | I30: Unit Price | J30: Extended Price
A31: 1001 | B31: CPFF | C31: F-16 O-Level Handheld/Pre-load Tester Engineering and Manufacturing Development (EMD) | D31: 1 | E31: LO | F31: ='Cost Format A_CLIN X001'!I68 -> 0 | G31: ='Cost Format A_CLIN X001'!I69 -> 0 | H31: ='Cost Format A_CLIN X001'!I70 -> 0 | I31: =+SUM(F31:H31) -> 0 | J31: =+D31*I31 -> 0
A32: 1002 | B32: CPFF | C32: F-15 O-Level Handheld/Pre-load Tester EMD | D32: 1 | E32: LO | F32: ='Cost Format A_CLIN X002'!I68 -> 0 | G32: ='Cost Format A_CLIN X002'!I69 -> 0 | H32: ='Cost Format A_CLIN X002'!I70 -> 0 | I32: =+SUM(F32:H32) -> 0 | J32: =+D32*I32 -> 0
A33: 1003 | B33: CPFF | C33: A-10 O-Level Handheld/Pre-load Tester EMD | D33: 1 | E33: LO | F33: ='Cost Format A_CLIN X003'!I68 -> 0 | G33: ='Cost Format A_CLIN X003'!I69 -> 0 | H33: ='Cost Format A_CLIN X003'!I70 -> 0 | I33: =+SUM(F33:H33) -> 0 | J33: =+D33*I33 -> 0
A34: 1004 | B34: CPFF | C34: F-16 I-Level Fault Isolation Tester EMD | D34: 1 | E34: LO | F34: ='Cost Format A_CLIN X004'!I68 -> 0 | G34: ='Cost Format A_CLIN X004'!I69 -> 0 | H34: ='Cost Format A_CLIN X004'!I70 -> 0 | I34: =+SUM(F34:H34) -> 0 | J34: =+D34*I34 -> 0
A35: 1005 | B35: CPFF | C35: F-15 I-Level Fault Isolation Tester EMD | D35: 1 | E35: LO | F35: ='Cost Format A_CLIN X005'!I68 -> 0 | G35: ='Cost Format A_CLIN X005'!I69 -> 0 | H35: ='Cost Format A_CLIN X005'!I70 -> 0 | I35: =+SUM(F35:H35) -> 0 | J35: =+D35*I35 -> 0
A36: 1006 | B36: CPFF | C36: A-10 I-Level Fault Isolation Tester EMD | D36: 1 | E36: LO | F36: ='Cost Format A_CLIN X006'!I68 -> 0 | G36: ='Cost Format A_CLIN X006'!I69 -> 0 | H36: ='Cost Format A_CLIN X006'!I70 -> 0 | I36: =+SUM(F36:H36) -> 0 | J36: =+D36*I36 -> 0
A37: 1007 | B37: FFP | C37: F-16 O-Level Handheld/Pre-load Tester Logistical Support | D37: 1 | E37: LO | I37: ='FFP CLINs'!H9 -> 0 | J37: =+D37*I37 -> 0
A38: 1008 | B38: FFP | C38: F-16 O-Level Handheld Tester LRIP production | D38: 10 | E38: EA | I38: ='FFP CLINs'!H13 -> 0 | J38: =+D38*I38 -> 0
A39: 1009 | B39: FFP | C39: Deliver F-16 O-Level Handheld Tester Kits | D39: 83 | E39: EA | I39: ='FFP CLINs'!H17 -> 0 | J39: =+D39*I39 -> 0
A40: 1010 | B40: FFP | C40: Program Management | D40: 1 | E40: LO | I40: ='FFP CLINs'!H21 -> 0 | J40: =+D40*I40 -> 0
A41: 1011 | B41: CPFF | C41: Support Government Testing | D41: 1 | E41: LO | F41: ='Cost Format A_Gov Testing CLINs'!E68 -> 0 | G41: ='Cost Format A_Gov Testing CLINs'!E69 -> 0 | H41: ='Cost Format A_Gov Testing CLINs'!E70 -> 0 | I41: =+SUM(F41:H41) -> 0 | J41: =+D41*I41 -> 0
A42: 1012 | B42: CRNF | C42: Travel | D42: 1 | E42: LO | F42: ='Cost Format A_Travel CLINs'!I25 -> 0 | G42: ='Cost Format A_Travel CLINs'!I26 -> 0 | I42: =+SUM(F42:H42) -> 0 | J42: =+D42*I42 -> 0
A43: 1013 | B43: FFP | C43: Government Data Rights | D43: 1 | E43: LO | I43: ='FFP CLINs'!H25 -> 0 | J43: =+D43*I43 -> 0
...

Sheet FFP CLINs
B1: Notes:
B2: 1. The prime offeror shall enter a proposed unit price per CLIN in the yellow-highlighted cells below.
B3: 2. Each Firm Fixed Price shall be rounded to the nearest whole dollar.
B4: 3. The prime offeror shall ensure the cells below are linked correctly to the CLIN cells on worksheet "Cost Format C_CLIN Summary".
B6: Basic Period (12 Months) | F6: Option Period I (12 Months) | J6: Option Period II (12 Months) | N6: Option Period III (12 Months) | R6: Option Period IV (12 Months)
B7: CLIN 0007 | F7: CLIN 1007 | J7: CLIN 2006 | N7: CLIN 3005 | R7: CLIN 4003
B8: Qty | C8: Unit | D8: Proposed Unit Price | F8: Qty | G8: Unit | H8: Proposed Unit Price | J8: Qty | K8: Unit | L8: Proposed Unit Price | N8: Qty | O8: Unit | P8: Proposed Unit Price | R8: Qty | S8: Unit | T8: Proposed Unit Price
B9: ='Cost Format C_CLIN Summary'!D16 -> 4 | C9: ='Cost Format C_CLIN Summary'!E16 -> EA | F9: ='Cost Format C_CLIN Summary'!D37 -> 1 | G9: ='Cost Format C_CLIN Summary'!E37 -> LO | J9: ='Cost Format C_CLIN Summary'!D54 -> 1 | K9: ='Cost Format C_CLIN Summary'!E54 -> LO | N9: ='Cost Format C_CLIN Summary'!D73 -> 1 | O9: ='Cost Format C_CLIN Summary'!E73 -> LO | R9: ='Cost Format C_CLIN Summary'!D90 -> 1 | S9: ='Cost Format C_CLIN Summary'!E90 -> LO
B11: CLIN 0008 | F11: CLIN 1008 | J11: CLIN 2007 | N11: CLIN 3006 | R11: CLIN 4004
B12: Qty | C12: Unit | D12: Proposed Unit Price | F12: Qty | G12: Unit | H12: Proposed Unit Price | J12: Qty | K12: Unit | L12: Proposed Unit Price | N12: Qty | O12: Unit | P12: Proposed Unit Price | R12: Qty | S12: Unit | T12: Proposed Unit Price
B13: ='Cost Format C_CLIN Summary'!D17 -> 4 | C13: ='Cost Format C_CLIN Summary'!E17 -> EA | F13: ='Cost Format C_CLIN Summary'!D38 -> 10 | G13: ='Cost Format C_CLIN Summary'!E38 -> EA | J13: ='Cost Format C_CLIN Summary'!D55 -> 1 | K13: ='Cost Format C_CLIN Summary'!E55 -> LO | N13: ='Cost Format C_CLIN Summary'!D74 -> 1 | O13: ='Cost Format C_CLIN Summary'!E74 -> LO | R13: ='Cost Format C_CLIN Summary'!D91 -> 75 | S13: ='Cost Format C_CLIN Summary'!E91 -> EA
B15: CLIN 0009 | F15: CLIN 1009 | J15: CLIN 2008 | N15: CLIN 3007 | R15: CLIN 4005
B16: Qty | C16: Unit | D16: Proposed Unit Price | F16: Qty | G16: Unit | H16: Proposed Unit Price | J16: Qty | K16: Unit | L16: Proposed Unit Price | N16: Qty | O16: Unit | P16: Proposed Unit Price | R16: Qty | S16: Unit | T16: Proposed Unit Price
B17: ='Cost Format C_CLIN Summary'!D18 -> 4 | C17: ='Cost Format C_CLIN Summary'!E18 -> EA | F17: ='Cost Format C_CLIN Summary'!D39 -> 83 | G17: ='Cost Format C_CLIN Summary'!E39 -> EA | J17: ='Cost Format C_CLIN Summary'!D56 -> 210 | K17: ='Cost Format C_CLIN Summary'!E56 -> EA | N17: ='Cost Format C_CLIN Summary'!D75 -> 64 | O17: ='Cost Format C_CLIN Summary'!E75 -> EA | R17: ='Cost Format C_CLIN Summary'!D92 -> 2 | S17: ='Cost Format C_CLIN Summary'!E92 -> EA
B19: CLIN 0010 | F19: CLIN 1010 | J19: CLIN 2009 | N19: CLIN 3008 | R19: CLIN 4006
B20: Qty | C20: Unit | D20: Proposed Unit Price | F20: Qty | G20: Unit | H20: Proposed Unit Price | J20: Qty | K20: Unit | L20: Proposed Unit Price | N20: Qty | O20: Unit | P20: Proposed Unit Price | R20: Qty | S20: Unit | T20: Proposed Unit Price
B21: ='Cost Format C_CLIN Summary'!D19 -> 1 | C21: ='Cost Format C_CLIN Summary'!E19 -> LO | F21: ='Cost Format C_CLIN Summary'!D40 -> 1 | G21: ='Cost Format C_CLIN Summary'!E40 -> LO | J21: ='Cost Format C_CLIN Summary'!D57 -> 10 | K21: ='Cost Format C_CLIN Summary'!E57 -> EA | N21: ='Cost Format C_CLIN Summary'!D76 -> 5 | O21: ='Cost Format C_CLIN Summary'!E76 -> EA | R21: ='Cost Format C_CLIN Summary'!D93 -> 40 | S21: ='Cost Format C_CLIN Summary'!E93 -> EA
B23: CLIN 0011 | F23: CLIN 1013 | J23: CLIN 2010 | N23: CLIN 3009 | R23: CLIN 4007
B24: Qty | C24: Unit | D24: Proposed Unit Price | F24: Qty | G24: Unit | H24: Proposed Unit Price | J24: Qty | K24: Unit | L24: Proposed Unit Price | N24: Qty | O24: Unit | P24: Proposed Unit Price | R24: Qty | S24: Unit | T24: Proposed Unit Price
B25: ='Cost Format C_CLIN Summary'!D20 -> 1 | C25: ='Cost Format C_CLIN Summary'!E20 -> LO | F25: ='Cost Format C_CLIN Summary'!D43 -> 1 | G25: ='Cost Format C_CLIN Summary'!E43 -> LO | J25: ='Cost Format C_CLIN Summary'!D58 -> 162 | K25: ='Cost Format C_CLIN Summary'!E58 -> EA | N25: ='Cost Format C_CLIN Summary'!D77 -> 5 | O25: ='Cost Format C_CLIN Summary'!E77 -> EA | R25: ='Cost Format C_CLIN Summary'!D94 -> 1 | S25: ='Cost Format C_CLIN Summary'!E94 -> LO
B27: CLIN 0012 | J27: CLIN 2011 | N27: CLIN 3010 | R27: CLIN 4010
B28: Qty | C28: Unit | D28: Proposed Unit Price | J28: Qty | K28: Unit | L28: Proposed Unit Price | N28: Qty | O28: Unit | P28: Proposed Unit Price | R28: Qty | S28: Unit | T28: Proposed Unit Price
B29: ='Cost Format C_CLIN Summary'!D21 -> 1 | C29: ='Cost Format C_CLIN Summary'!E21 -> LO | J29: ='Cost Format C_CLIN Summary'!D59 -> 4 | K29: ='Cost Format C_CLIN Summary'!E59 -> EA | N29: ='Cost Format C_CLIN Summary'!D78 -> 138 | O29: ='Cost Format C_CLIN Summary'!E78 -> EA | R29: ='Cost Format C_CLIN Summary'!D97 -> 1 | S29: ='Cost Format C_CLIN Summary'!E97 -> LO
B31: CLIN 0013 | J31: CLIN 2012 | N31: CLIN 3011
B32: Qty | C32: Unit | D32: Proposed Unit Price | J32: Qty | K32: Unit | L32: Proposed Unit Price | N32: Qty | O32: Unit | P32: Proposed Unit Price
B33: ='Cost Format C_CLIN Summary'!D22 -> 1 | C33: ='Cost Format C_CLIN Summary'!E22 -> LO | J33: ='Cost Format C_CLIN Summary'!D60 -> 1 | K33: ='Cost Format C_CLIN Summary'!E60 -> LO | N33: ='Cost Format C_CLIN Summary'!D79 -> 1 | O33: ='Cost Format C_CLIN Summary'!E79 -> LO
B35: CLIN 0016 | J35: CLIN 2015 | N35: CLIN 3014
B36: Qty | C36: Unit | D36: Proposed Unit Price | J36: Qty | K36: Unit | L36: Proposed Unit Price | N36: Qty | O36: Unit | P36: Proposed Unit Price
B37: ='Cost Format C_CLIN Summary'!D25 -> 1 | C37: ='Cost Format C_CLIN Summary'!E25 -> LO | J37: ='Cost Format C_CLIN Summary'!D63 -> 1 | K37: ='Cost Format C_CLIN Summary'!E63 -> LO | N37: ='Cost Format C_CLIN Summary'!D82 -> 1 | O37: ='Cost Format C_CLIN Summary'!E82 -> LO

Sheet Cost Format A_CLIN X001
B1: Notes:
B2: 1. The format of this worksheet may be revised as required to be consistent with the major subcontractor's approved accounting system.
B3: 2. The Prime Offeror shall propose labor hours, material costs, and other direct costs in the yellow-highlighted cells below.
B4: 3. The Prime Offeror shall ensure the yellow-highlighted rate cells below are linked correctly from the relevant labor rate and add-on factors in the 'Cost Format B_PRIME Rates' worksheet.
B5: 4. The proposed factors will be applied to the proposed labor hours, material cost, and other direct costs.
B6: 5. Definitions of the labor categories and add-on factors are included in the 'Cost Format B_PRIME Rate Desc' worksheet.
B7: 6. Each CPFF/CPIF Cost, COM and Fee shall be rounded to the nearest whole dollar.
B10: CLINs 0001 & 1001: CPFF | C10: Proposed Prices (Labor) | G10: Proposed Prices (Labor) | L10: CLINs 2001, 3001, & 4001: CPIF | M10: Proposed Prices (Labor) | Q10: Proposed Prices (Labor) | U10: Proposed Prices (Labor)
C11: 0001: F-16 O-Level Handheld/Pre-load Tester Prototype Design and Digital Development - Basic Period | G11: 1001: F-16 O-Level Handheld/Pre-load Tester EMD - Option Period 1 | M11: 2001: F-15 O-Level Handheld/Pre-load Tester EMD - Option Period 2 | Q11: 3001: A-10 O-Level Handheld/Pre-load Tester EMD - Option Period 3 | U11: 4001: F-15 I-Level Fault Isolation Tester EMD - Option Period 4
B12: Labor Category | C12: Hours | D12: Rates | E12: Cost | G12: Hours | H12: Rates | I12: Cost | L12: Labor Category | M12: Hours | N12: Rates | O12: Cost | Q12: Hours | R12: Rates | S12: Cost | U12: Hours | V12: Rates | W12: Cost
B13: Labor Category 1: [INSERT LABOR CATEGORY NAME HERE] | D13: 0 | E13: =+C13*D13 -> 0 | H13: 0 | I13: =+G13*H13 -> 0 | L13: Labor Category 1: [INSERT LABOR CATEGORY NAME HERE] | N13: 0 | O13: =+M13*N13 -> 0 | R13: 0 | S13: =+Q13*R13 -> 0 | V13: 0 | W13: =+U13*V13 -> 0
B14: Labor Category 2: [INSERT LABOR CATEGORY NAME HERE] | D14: 0 | E14: =+C14*D14 -> 0 | H14: 0 | I14: =+G14*H14 -> 0 | L14: Labor Category 2: [INSERT LABOR CATEGORY NAME HERE] | N14: 0 | O14: =+M14*N14 -> 0 | R14: 0 | S14: =+Q14*R14 -> 0 | V14: 0 | W14: =+U14*V14 -> 0
B15: Labor Category 3: [INSERT LABOR CATEGORY NAME HERE] | D15: 0 | E15: =+C15*D15 -> 0 | H15: 0 | I15: =+G15*H15 -> 0 | L15: Labor Category 3: [INSERT LABOR CATEGORY NAME HERE] | N15: 0 | O15: =+M15*N15 -> 0 | R15: 0 | S15: =+Q15*R15 -> 0 | V15: 0 | W15: =+U15*V15 -> 0
B16: Labor Category 4: [INSERT LABOR CATEGORY NAME HERE] | D16: 0 | E16: =+C16*D16 -> 0 | H16: 0 | I16: =+G16*H16 -> 0 | L16: Labor Category 4: [INSERT LABOR CATEGORY NAME HERE] | N16: 0 | O16: =+M16*N16 -> 0 | R16: 0 | S16: =+Q16*R16 -> 0 | V16: 0 | W16: =+U16*V16 -> 0
B17: Labor Category 5: [INSERT LABOR CATEGORY NAME HERE] | D17: 0 | E17: =+C17*D17 -> 0 | H17: 0 | I17: =+G17*H17 -> 0 | L17: Labor Category 5: [INSERT LABOR CATEGORY NAME HERE] | N17: 0 | O17: =+M17*N17 -> 0 | R17: 0 | S17: =+Q17*R17 -> 0 | V17: 0 | W17: =+U17*V17 -> 0
B18: Labor Category 6: [INSERT LABOR CATEGORY NAME HERE] | D18: 0 | E18: =+C18*D18 -> 0 | H18: 0 | I18: =+G18*H18 -> 0 | L18: Labor Category 6: [INSERT LABOR CATEGORY NAME HERE] | N18: 0 | O18: =+M18*N18 -> 0 | R18: 0 | S18: =+Q18*R18 -> 0 | V18: 0 | W18: =+U18*V18 -> 0
B19: Labor Category 7: [INSERT LABOR CATEGORY NAME HERE] | D19: 0 | E19: =+C19*D19 -> 0 | H19: 0 | I19: =+G19*H19 -> 0 | L19: Labor Category 7: [INSERT LABOR CATEGORY NAME HERE] | N19: 0 | O19: =+M19*N19 -> 0 | R19: 0 | S19: =+Q19*R19 -> 0 | V19: 0 | W19: =+U19*V19 -> 0
B20: Labor Category 8: [INSERT LABOR CATEGORY NAME HERE] | D20: 0 | E20: =+C20*D20 -> 0 | H20: 0 | I20: =+G20*H20 -> 0 | L20: Labor Category 8: [INSERT LABOR CATEGORY NAME HERE] | N20: 0 | O20: =+M20*N20 -> 0 | R20: 0 | S20: =+Q20*R20 -> 0 | V20: 0 | W20: =+U20*V20 -> 0
B21: Labor Category 9: [INSERT LABOR CATEGORY NAME HERE] | D21: 0 | E21: =+C21*D21 -> 0 | H21: 0 | I21: =+G21*H21 -> 0 | L21: Labor Category 9: [INSERT LABOR CATEGORY NAME HERE] | N21: 0 | O21: =+M21*N21 -> 0 | R21: 0 | S21: =+Q21*R21 -> 0 | V21: 0 | W21: =+U21*V21 -> 0
B22: Labor Category 10: [INSERT LABOR CATEGORY NAME HERE] | D22: 0 | E22: =+C22*D22 -> 0 | H22: 0 | I22: =+G22*H22 -> 0 | L22: Labor Category 10: [INSERT LABOR CATEGORY NAME HERE] | N22: 0 | O22: =+M22*N22 -> 0 | R22: 0 | S22: =+Q22*R22 -> 0 | V22: 0 | W22: =+U22*V22 -> 0
B23: Labor Category 11: [INSERT LABOR CATEGORY NAME HERE] | D23: 0 | E23: =+C23*D23 -> 0 | H23: 0 | I23: =+G23*H23 -> 0 | L23: Labor Category 11: [INSERT LABOR CATEGORY NAME HERE] | N23: 0 | O23: =+M23*N23 -> 0 | R23: 0 | S23: =+Q23*R23 -> 0 | V23: 0 | W23: =+U23*V23 -> 0
B24: Labor Category 12: [INSERT LABOR CATEGORY NAME HERE] | D24: 0 | E24: =+C24*D24 -> 0 | H24: 0 | I24: =+G24*H24 -> 0 | L24: Labor Category 12: [INSERT LABOR CATEGORY NAME HERE] | N24: 0 | O24: =+M24*N24 -> 0 | R24: 0 | S24: =+Q24*R24 -> 0 | V24: 0 | W24: =+U24*V24 -> 0
B25: Labor Category 13: [INSERT LABOR CATEGORY NAME HERE] | D25: 0 | E25: =+C25*D25 -> 0 | H25: 0 | I25: =+G25*H25 -> 0 | L25: Labor Category 13: [INSERT LABOR CATEGORY NAME HERE] | N25: 0 | O25: =+M25*N25 -> 0 | R25: 0 | S25: =+Q25*R25 -> 0 | V25: 0 | W25: =+U25*V25 -> 0
B26: TOTAL HOURS/COST | C26: =SUM(C13:C25) -> 0 | E26: =SUM(E13:E25) -> 0 | G26: =SUM(G13:G25) -> 0 | I26: =SUM(I13:I25) -> 0 | L26: TOTAL HOURS/COST | M26: =SUM(M13:M25) -> 0 | O26: =SUM(O13:O25) -> 0 | Q26: =SUM(Q13:Q25) -> 0 | S26: =SUM(S13:S25) -> 0 | U26: =SUM(U13:U25) -> 0 | W26: =SUM(W13:W25) -> 0
C27: Base | D27: Rates | E27: Cost | G27: Base | H27: Rates | I27: Cost | M27: Base | N27: Rates | O27: Cost | Q27: Base | R27: Rates | S27: Cost | U27: Base | V27: Rates | W27: Cost
B28: Proposed Add-on Factor (Fringe) | C28: =+E26 -> 0 | D28: 0 | E28: =+C28*D28 -> 0 | G28: =+I26 -> 0 | H28: 0 | I28: =+G28*H28 -> 0 | L28: Proposed Add-on Factor (Fringe) | M28: =+O26 -> 0 | N28: 0 | O28: =+M28*N28 -> 0 | Q28: =+S26 -> 0 | R28: 0 | S28: =+Q28*R28 -> 0 | U28: =+W26 -> 0 | V28: 0 | W28: =+U28*V28 -> 0
B29: Proposed Add-on Factor (Overhead) | C29: =+C28+E28 -> 0 | D29: 0 | E29: =+C29*D29 -> 0 | G29: =+G28+I28 -> 0 | H29: 0 | I29: =+G29*H29 -> 0 | L29: Proposed Add-on Factor (Overhead) | M29: =+M28+O28 -> 0 | N29: 0 | O29: =+M29*N29 -> 0 | Q29: =+Q28+S28 -> 0 | R29: 0 | S29: =+Q29*R29 -> 0 | U29: =+U28+W28 -> 0 | V29: 0 | W29: =+U29*V29 -> 0
B30: Proposed Add-on Factor (G&A) | C30: =+C29+E29 -> 0 | D30: 0 | E30: =+C30*D30 -> 0 | G30: =+G29+I29 -> 0 | H30: 0 | I30: =+G30*H30 -> 0 | L30: Proposed Add-on Factor (G&A) | M30: =+M29+O29 -> 0 | N30: 0 | O30: =+M30*N30 -> 0 | Q30: =+Q29+S29 -> 0 | R30: 0 | S30: =+Q30*R30 -> 0 | U30: =+U29+W29 -> 0 | V30: 0 | W30: =+U30*V30 -> 0
B31: Proposed Add-on Factor (COM) | C31: =+C28 -> 0 | D31: 0 | E31: =+C31*D31 -> 0 | G31: =+G28 -> 0 | H31: 0 | I31: =+G31*H31 -> 0 | L31: Proposed Add-on Factor (COM) | M31: =+M28 -> 0 | N31: 0 | O31: =+M31*N31 -> 0 | Q31: =+Q28 -> 0 | R31: 0 | S31: =+Q31*R31 -> 0 | U31: =+U28 -> 0 | V31: 0 | W31: =+U31*V31 -> 0
B32: Proposed Add-on Factor (Fee) | C32: =+C30+E30 -> 0 | D32: 0 | E32: =+C32*D32 -> 0 | G32: =+G30+I30 -> 0 | H32: 0 | I32: =+G32*H32 -> 0 | L32: Proposed Add-on Factor (Fee) | M32: =+M30+O30 -> 0 | N32: 0 | O32: =+M32*N32 -> 0 | Q32: =+Q30+S30 -> 0 | R32: 0 | S32: =+Q32*R32 -> 0 | U32: =+U30+W30 -> 0 | V32: 0 | W32: =+U32*V32 -> 0
B33: Total Proposed Cost | E33: =+SUM(E26,E28,E29,E30) -> 0 | I33: =+SUM(I26,I28,I29,I30) -> 0 | L33: Total Proposed Target Cost | O33: =+SUM(O26,O28,O29,O30) -> 0 | S33: =+SUM(S26,S28,S29,S30) -> 0 | W33: =+SUM(W26,W28,W29,W30) -> 0
B34: Total Proposed COM | E34: =+E31 -> 0 | I34: =+I31 -> 0 | L34: Total Proposed Target COM | O34: =+O31 -> 0 | S34: =+S31 -> 0 | W34: =+W31 -> 0
B35: Total Proposed Fee | E35: =+E32 -> 0 | I35: =+I32 -> 0 | L35: Total Proposed Target Fee | O35: =+O32 -> 0 | S35: =+S32 -> 0 | W35: =+W32 -> 0
B36: Total Proposed Price | E36: =SUM(E33:E35) -> 0 | I36: =SUM(I33:I35) -> 0 | L36: Total Proposed Target Price | O36: =SUM(O33:O35) -> 0 | S36: =SUM(S33:S35) -> 0 | W36: =SUM(W33:W35) -> 0
B39: =B10 -> CLINs 0001 & 1001: CPFF | C39: Proposed Prices (Material) | G39: Proposed Prices (Material) | M39: Proposed Prices (Material) | Q39: Proposed Prices (Material) | U39: Proposed Prices (Material)
C40: =C11 -> 0001: F-16 O-Level Handheld/Pre-load Tester Prototype Design and Digital Development - Basic Period | G40: =G11 -> 1001: F-16 O-Level Handheld/Pre-load Tester EMD - Option Period 1 | M40: =M11 -> 2001: F-15 O-Level Handheld/Pre-load Tester EMD - Option Period 2 | Q40: =Q11 -> 3001: A-10 O-Level Handheld/Pre-load Tester EMD - Option Period 3 | U40: =U11 -> 4001: F-15 I-Level Fault Isolation Tester EMD - Option Period 4
C41: Base | D41: Rates | E41: Cost | G41: Base | H41: Rates | I41: Cost | M41: Base | N41: Rates | O41: Cost | Q41: Base | R41: Rates | S41: Cost | U41: Base | V41: Rates | W41: Cost
B42: Total Proposed Material Cost | L42: Total Proposed Material Cost
B43: Proposed Add-on Factor (Overhead) | C43: =+E42 -> 0 | D43: 0 | E43: =+C43*D43 -> 0 | G43: =+I42 -> 0 | H43: 0 | I43: =+G43*H43 -> 0 | L43: Proposed Add-on Factor (Overhead) | M43: =+O42 -> 0 | N43: 0 | O43: =+M43*N43 -> 0 | Q43: =+S42 -> 0 | R43: 0 | S43: =+Q43*R43 -> 0 | U43: =+W42 -> 0 | V43: 0 | W43: =+U43*V43 -> 0
B44: Proposed Add-on Factor (G&A) | C44: =+C43+E43 -> 0 | D44: 0 | E44: =+C44*D44 -> 0 | G44: =+G43+I43 -> 0 | H44: 0 | I44: =+G44*H44 -> 0 | L44: Proposed Add-on Factor (G&A) | M44: =+M43+O43 -> 0 | N44: 0 | O44: =+M44*N44 -> 0 | Q44: =+Q43+S43 -> 0 | R44: 0 | S44: =+Q44*R44 -> 0 | U44: =+U43+W43 -> 0 | V44: 0 | W44: =+U44*V44 -> 0
...

Sheet Cost Format A_CLIN X002
B1: Notes:
B2: 1. The format of this worksheet may be revised as required to be consistent with the major subcontractor's approved accounting system.
B3: 2. The Prime Offeror shall propose labor hours, material costs, and other direct costs in the yellow-highlighted cells below.
B4: 3. The Prime Offeror shall ensure the yellow-highlighted rate cells below are linked correctly from the relevant labor rate and add-on factors in the 'Cost Format B_PRIME Rates' worksheet.
B5: 4. The proposed factors will be applied to the proposed labor hours, material cost, and other direct costs.
B6: 5. Definitions of the labor categories and add-on factors are included in the 'Cost Format B_PRIME Rate Desc' worksheet.
B7: 6. Each CPFF/CPIF Cost, COM and Fee shall be rounded to the nearest whole dollar.
B10: CLINs 0002 & 1002: CPFF | C10: Proposed Prices (Labor) | G10: Proposed Prices (Labor) | L10: CLINs 2002, 3002, & 4002: CPIF | M10: Proposed Prices (Labor) | Q10: Proposed Prices (Labor) | U10: Proposed Prices (Labor)
C11: 0002: F-15 O-Level Handheld/Pre-load Tester Prototype design and digital development - Basic Period | G11: 1002: F-15 O-Level Handheld/Pre-load Tester EMD - Option Period 1 | M11: 2002: A-10 O-Level Handheld/Pre-load Tester EMD - Option Period 2 | Q11: 3002: F-16 I-Level Fault Isolation Tester EMD - Option Period 3 | U11: 4002: A-10 I-Level Fault Isolation Tester EMD - Option Period 4
B12: Labor Category | C12: Hours | D12: Rates | E12: Cost | G12: Hours | H12: Rates | I12: Cost | L12: Labor Category | M12: Hours | N12: Rates | O12: Cost | Q12: Hours | R12: Rates | S12: Cost | U12: Hours | V12: Rates | W12: Cost
B13: Labor Category 1: [INSERT LABOR CATEGORY NAME HERE] | D13: 0 | E13: =+C13*D13 -> 0 | H13: 0 | I13: =+G13*H13 -> 0 | L13: Labor Category 1: [INSERT LABOR CATEGORY NAME HERE] | N13: 0 | O13: =+M13*N13 -> 0 | R13: 0 | S13: =+Q13*R13 -> 0 | V13: 0 | W13: =+U13*V13 -> 0
B14: Labor Category 2: [INSERT LABOR CATEGORY NAME HERE] | D14: 0 | E14: =+C14*D14 -> 0 | H14: 0 | I14: =+G14*H14 -> 0 | L14: Labor Category 2: [INSERT LABOR CATEGORY NAME HERE] | N14: 0 | O14: =+M14*N14 -> 0 | R14: 0 | S14: =+Q14*R14 -> 0 | V14: 0 | W14: =+U14*V14 -> 0
B15: Labor Category 3: [INSERT LABOR CATEGORY NAME HERE] | D15: 0 | E15: =+C15*D15 -> 0 | H15: 0 | I15: =+G15*H15 -> 0 | L15: Labor Category 3: [INSERT LABOR CATEGORY NAME HERE] | N15: 0 | O15: =+M15*N15 -> 0 | R15: 0 | S15: =+Q15*R15 -> 0 | V15: 0 | W15: =+U15*V15 -> 0
B16: Labor Category 4: [INSERT LABOR CATEGORY NAME HERE] | D16: 0 | E16: =+C16*D16 -> 0 | H16: 0 | I16: =+G16*H16 -> 0 | L16: Labor Category 4: [INSERT LABOR CATEGORY NAME HERE] | N16: 0 | O16: =+M16*N16 -> 0 | R16: 0 | S16: =+Q16*R16 -> 0 | V16: 0 | W16: =+U16*V16 -> 0
B17: Labor Category 5: [INSERT LABOR CATEGORY NAME HERE] | D17: 0 | E17: =+C17*D17 -> 0 | H17: 0 | I17: =+G17*H17 -> 0 | L17: Labor Category 5: [INSERT LABOR CATEGORY NAME HERE] | N17: 0 | O17: =+M17*N17 -> 0 | R17: 0 | S17: =+Q17*R17 -> 0 | V17: 0 | W17: =+U17*V17 -> 0
B18: Labor Category 6: [INSERT LABOR CATEGORY NAME HERE] | D18: 0 | E18: =+C18*D18 -> 0 | H18: 0 | I18: =+G18*H18 -> 0 | L18: Labor Category 6: [INSERT LABOR CATEGORY NAME HERE] | N18: 0 | O18: =+M18*N18 -> 0 | R18: 0 | S18: =+Q18*R18 -> 0 | V18: 0 | W18: =+U18*V18 -> 0
B19: Labor Category 7: [INSERT LABOR CATEGORY NAME HERE] | D19: 0 | E19: =+C19*D19 -> 0 | H19: 0 | I19: =+G19*H19 -> 0 | L19: Labor Category 7: [INSERT LABOR CATEGORY NAME HERE] | N19: 0 | O19: =+M19*N19 -> 0 | R19: 0 | S19: =+Q19*R19 -> 0 | V19: 0 | W19: =+U19*V19 -> 0
B20: Labor Category 8: [INSERT LABOR CATEGORY NAME HERE] | D20: 0 | E20: =+C20*D20 -> 0 | H20: 0 | I20: =+G20*H20 -> 0 | L20: Labor Category 8: [INSERT LABOR CATEGORY NAME HERE] | N20: 0 | O20: =+M20*N20 -> 0 | R20: 0 | S20: =+Q20*R20 -> 0 | V20: 0 | W20: =+U20*V20 -> 0
B21: Labor Category 9: [INSERT LABOR CATEGORY NAME HERE] | D21: 0 | E21: =+C21*D21 -> 0 | H21: 0 | I21: =+G21*H21 -> 0 | L21: Labor Category 9: [INSERT LABOR CATEGORY NAME HERE] | N21: 0 | O21: =+M21*N21 -> 0 | R21: 0 | S21: =+Q21*R21 -> 0 | V21: 0 | W21: =+U21*V21 -> 0
B22: Labor Category 10: [INSERT LABOR CATEGORY NAME HERE] | D22: 0 | E22: =+C22*D22 -> 0 | H22: 0 | I22: =+G22*H22 -> 0 | L22: Labor Category 10: [INSERT LABOR CATEGORY NAME HERE] | N22: 0 | O22: =+M22*N22 -> 0 | R22: 0 | S22: =+Q22*R22 -> 0 | V22: 0 | W22: =+U22*V22 -> 0
B23: Labor Category 11: [INSERT LABOR CATEGORY NAME HERE] | D23: 0 | E23: =+C23*D23 -> 0 | H23: 0 | I23: =+G23*H23 -> 0 | L23: Labor Category 11: [INSERT LABOR CATEGORY NAME HERE] | N23: 0 | O23: =+M23*N23 -> 0 | R23: 0 | S23: =+Q23*R23 -> 0 | V23: 0 | W23: =+U23*V23 -> 0
B24: Labor Category 12: [INSERT LABOR CATEGORY NAME HERE] | D24: 0 | E24: =+C24*D24 -> 0 | H24: 0 | I24: =+G24*H24 -> 0 | L24: Labor Category 12: [INSERT LABOR CATEGORY NAME HERE] | N24: 0 | O24: =+M24*N24 -> 0 | R24: 0 | S24: =+Q24*R24 -> 0 | V24: 0 | W24: =+U24*V24 -> 0
B25: Labor Category 13: [INSERT LABOR CATEGORY NAME HERE] | D25: 0 | E25: =+C25*D25 -> 0 | H25: 0 | I25: =+G25*H25 -> 0 | L25: Labor Category 13: [INSERT LABOR CATEGORY NAME HERE] | N25: 0 | O25: =+M25*N25 -> 0 | R25: 0 | S25: =+Q25*R25 -> 0 | V25: 0 | W25: =+U25*V25 -> 0
B26: TOTAL HOURS/COST | C26: =SUM(C13:C25) -> 0 | E26: =SUM(E13:E25) -> 0 | G26: =SUM(G13:G25) -> 0 | I26: =SUM(I13:I25) -> 0 | L26: TOTAL HOURS/COST | M26: =SUM(M13:M25) -> 0 | O26: =SUM(O13:O25) -> 0 | Q26: =SUM(Q13:Q25) -> 0 | S26: =SUM(S13:S25) -> 0 | U26: =SUM(U13:U25) -> 0 | W26: =SUM(W13:W25) -> 0
C27: Base | D27: Rates | E27: Cost | G27: Base | H27: Rates | I27: Cost | M27: Base | N27: Rates | O27: Cost | Q27: Base | R27: Rates | S27: Cost | U27: Base | V27: Rates | W27: Cost
B28: Proposed Add-on Factor (Fringe) | C28: =+E26 -> 0 | D28: 0 | E28: =+C28*D28 -> 0 | G28: =+I26 -> 0 | H28: 0 | I28: =+G28*H28 -> 0 | L28: Proposed Add-on Factor (Fringe) | M28: =+O26 -> 0 | N28: 0 | O28: =+M28*N28 -> 0 | Q28: =+S26 -> 0 | R28: 0 | S28: =+Q28*R28 -> 0 | U28: =+W26 -> 0 | V28: 0 | W28: =+U28*V28 -> 0
B29: Proposed Add-on Factor (Overhead) | C29: =+C28+E28 -> 0 | D29: 0 | E29: =+C29*D29 -> 0 | G29: =+G28+I28 -> 0 | H29: 0 | I29: =+G29*H29 -> 0 | L29: Proposed Add-on Factor (Overhead) | M29: =+M28+O28 -> 0 | N29: 0 | O29: =+M29*N29 -> 0 | Q29: =+Q28+S28 -> 0 | R29: 0 | S29: =+Q29*R29 -> 0 | U29: =+U28+W28 -> 0 | V29: 0 | W29: =+U29*V29 -> 0
B30: Proposed Add-on Factor (G&A) | C30: =+C29+E29 -> 0 | D30: 0 | E30: =+C30*D30 -> 0 | G30: =+G29+I29 -> 0 | H30: 0 | I30: =+G30*H30 -> 0 | L30: Proposed Add-on Factor (G&A) | M30: =+M29+O29 -> 0 | N30: 0 | O30: =+M30*N30 -> 0 | Q30: =+Q29+S29 -> 0 | R30: 0 | S30: =+Q30*R30 -> 0 | U30: =+U29+W29 -> 0 | V30: 0 | W30: =+U30*V30 -> 0
B31: Proposed Add-on Factor (COM) | C31: =+C28 -> 0 | D31: 0 | E31: =+C31*D31 -> 0 | G31: =+G28 -> 0 | H31: 0 | I31: =+G31*H31 -> 0 | L31: Proposed Add-on Factor (COM) | M31: =+M28 -> 0 | N31: 0 | O31: =+M31*N31 -> 0 | Q31: =+Q28 -> 0 | R31: 0 | S31: =+Q31*R31 -> 0 | U31: =+U28 -> 0 | V31: 0 | W31: =+U31*V31 -> 0
B32: Proposed Add-on Factor (Fee) | C32: =+C30+E30 -> 0 | D32: 0 | E32: =+C32*D32 -> 0 | G32: =+G30+I30 -> 0 | H32: 0 | I32: =+G32*H32 -> 0 | L32: Proposed Add-on Factor (Fee) | M32: =+M30+O30 -> 0 | N32: 0 | O32: =+M32*N32 -> 0 | Q32: =+Q30+S30 -> 0 | R32: 0 | S32: =+Q32*R32 -> 0 | U32: =+U30+W30 -> 0 | V32: 0 | W32: =+U32*V32 -> 0
B33: Total Proposed Cost | E33: =+SUM(E26,E28,E29,E30) -> 0 | I33: =+SUM(I26,I28,I29,I30) -> 0 | L33: Total Proposed Target Cost | O33: =+SUM(O26,O28,O29,O30) -> 0 | S33: =+SUM(S26,S28,S29,S30) -> 0 | W33: =+SUM(W26,W28,W29,W30) -> 0
B34: Total Proposed COM | E34: =+E31 -> 0 | I34: =+I31 -> 0 | L34: Total Proposed Target COM | O34: =+O31 -> 0 | S34: =+S31 -> 0 | W34: =+W31 -> 0
B35: Total Proposed Fee | E35: =+E32 -> 0 | I35: =+I32 -> 0 | L35: Total Proposed Target Fee | O35: =+O32 -> 0 | S35: =+S32 -> 0 | W35: =+W32 -> 0
B36: Total Proposed Price | E36: =SUM(E33:E35) -> 0 | I36: =SUM(I33:I35) -> 0 | L36: Total Proposed Target Price | O36: =SUM(O33:O35) -> 0 | S36: =SUM(S33:S35) -> 0 | W36: =SUM(W33:W35) -> 0
B39: =B10 -> CLINs 0002 & 1002: CPFF | C39: Proposed Prices (Material) | G39: Proposed Prices (Material) | M39: Proposed Prices (Material) | Q39: Proposed Prices (Material) | U39: Proposed Prices (Material)
C40: =C11 -> 0002: F-15 O-Level Handheld/Pre-load Tester Prototype design and digital development - Basic Period | G40: =G11 -> 1002: F-15 O-Level Handheld/Pre-load Tester EMD - Option Period 1 | M40: =M11 -> 2002: A-10 O-Level Handheld/Pre-load Tester EMD - Option Period 2 | Q40: =Q11 -> 3002: F-16 I-Level Fault Isolation Tester EMD - Option Period 3 | U40: =U11 -> 4002: A-10 I-Level Fault Isolation Tester EMD - Option Period 4
C41: Base | D41: Rates | E41: Cost | G41: Base | H41: Rates | I41: Cost | M41: Base | N41: Rates | O41: Cost | Q41: Base | R41: Rates | S41: Cost | U41: Base | V41: Rates | W41: Cost
B42: Total Proposed Material Cost | L42: Total Proposed Material Cost
B43: Proposed Add-on Factor (Overhead) | C43: =+E42 -> 0 | D43: 0 | E43: =+C43*D43 -> 0 | G43: =+I42 -> 0 | H43: 0 | I43: =+G43*H43 -> 0 | L43: Proposed Add-on Factor (Overhead) | M43: =+O42 -> 0 | N43: 0 | O43: =+M43*N43 -> 0 | Q43: =+S42 -> 0 | R43: 0 | S43: =+Q43*R43 -> 0 | U43: =+W42 -> 0 | V43: 0 | W43: =+U43*V43 -> 0
B44: Proposed Add-on Factor (G&A) | C44: =+C43+E43 -> 0 | D44: 0 | E44: =+C44*D44 -> 0 | G44: =+G43+I43 -> 0 | H44: 0 | I44: =+G44*H44 -> 0 | L44: Proposed Add-on Factor (G&A) | M44: =+M43+O43 -> 0 | N44: 0 | O44: =+M44*N44 -> 0 | Q44: =+Q43+S43 -> 0 | R44: 0 | S44: =+Q44*R44 -> 0 | U44: =+U43+W43 -> 0 | V44: 0 | W44: =+U44*V44 -> 0
...

Sheet Cost Format A_CLIN X003
B1: Notes:
B2: 1. The format of this worksheet may be revised as required to be consistent with the major subcontractor's approved accounting system.
B3: 2. The Prime Offeror shall propose labor hours, material costs, and other direct costs in the yellow-highlighted cells below.
B4: 3. The Prime Offeror shall ensure the yellow-highlighted rate cells below are linked correctly from the relevant labor rate and add-on factors in the 'Cost Format B_PRIME Rates' worksheet.
B5: 4. The proposed factors will be applied to the proposed labor hours, material cost, and other direct costs.
B6: 5. Definitions of the labor categories and add-on factors are included in the 'Cost Format B_PRIME Rate Desc' worksheet.
B7: 6. Each CPFF/CPIF Cost, COM and Fee shall be rounded to the nearest whole dollar.
B10: CLINs 0003 & 1003: CPFF | C10: Proposed Prices (Labor) | G10: Proposed Prices (Labor) | L10: CLINs 2003 & 3003: CPIF | M10: Proposed Prices (Labor) | Q10: Proposed Prices (Labor)
C11: 0003: A-10 O-Level Handheld/Pre-load Tester Prototype design and digital development - Basic Period | G11: 1003: A-10 O-Level Handheld/Pre-load Tester EMD - Option Period 1 | M11: 2003: F-16 I-Level Fault Isolation Tester EMD - Option Period 2 | Q11: 3003: F-15 I-Level Fault Isolation Tester EMD - Option Period 3
B12: Labor Category | C12: Hours | D12: Rates | E12: Cost | G12: Hours | H12: Rates | I12: Cost | L12: Labor Category | M12: Hours | N12: Rates | O12: Cost | Q12: Hours | R12: Rates | S12: Cost
B13: Labor Category 1: [INSERT LABOR CATEGORY NAME HERE] | D13: 0 | E13: =+C13*D13 -> 0 | H13: 0 | I13: =+G13*H13 -> 0 | L13: Labor Category 1: [INSERT LABOR CATEGORY NAME HERE] | N13: 0 | O13: =+M13*N13 -> 0 | R13: 0 | S13: =+Q13*R13 -> 0
B14: Labor Category 2: [INSERT LABOR CATEGORY NAME HERE] | D14: 0 | E14: =+C14*D14 -> 0 | H14: 0 | I14: =+G14*H14 -> 0 | L14: Labor Category 2: [INSERT LABOR CATEGORY NAME HERE] | N14: 0 | O14: =+M14*N14 -> 0 | R14: 0 | S14: =+Q14*R14 -> 0
B15: Labor Category 3: [INSERT LABOR CATEGORY NAME HERE] | D15: 0 | E15: =+C15*D15 -> 0 | H15: 0 | I15: =+G15*H15 -> 0 | L15: Labor Category 3: [INSERT LABOR CATEGORY NAME HERE] | N15: 0 | O15: =+M15*N15 -> 0 | R15: 0 | S15: =+Q15*R15 -> 0
B16: Labor Category 4: [INSERT LABOR CATEGORY NAME HERE] | D16: 0 | E16: =+C16*D16 -> 0 | H16: 0 | I16: =+G16*H16 -> 0 | L16: Labor Category 4: [INSERT LABOR CATEGORY NAME HERE] | N16: 0 | O16: =+M16*N16 -> 0 | R16: 0 | S16: =+Q16*R16 -> 0
B17: Labor Category 5: [INSERT LABOR CATEGORY NAME HERE] | D17: 0 | E17: =+C17*D17 -> 0 | H17: 0 | I17: =+G17*H17 -> 0 | L17: Labor Category 5: [INSERT LABOR CATEGORY NAME HERE] | N17: 0 | O17: =+M17*N17 -> 0 | R17: 0 | S17: =+Q17*R17 -> 0
B18: Labor Category 6: [INSERT LABOR CATEGORY NAME HERE] | D18: 0 | E18: =+C18*D18 -> 0 | H18: 0 | I18: =+G18*H18 -> 0 | L18: Labor Category 6: [INSERT LABOR CATEGORY NAME HERE] | N18: 0 | O18: =+M18*N18 -> 0 | R18: 0 | S18: =+Q18*R18 -> 0
B19: Labor Category 7: [INSERT LABOR CATEGORY NAME HERE] | D19: 0 | E19: =+C19*D19 -> 0 | H19: 0 | I19: =+G19*H19 -> 0 | L19: Labor Category 7: [INSERT LABOR CATEGORY NAME HERE] | N19: 0 | O19: =+M19*N19 -> 0 | R19: 0 | S19: =+Q19*R19 -> 0
B20: Labor Category 8: [INSERT LABOR CATEGORY NAME HERE] | D20: 0 | E20: =+C20*D20 -> 0 | H20: 0 | I20: =+G20*H20 -> 0 | L20: Labor Category 8: [INSERT LABOR CATEGORY NAME HERE] | N20: 0 | O20: =+M20*N20 -> 0 | R20: 0 | S20: =+Q20*R20 -> 0
B21: Labor Category 9: [INSERT LABOR CATEGORY NAME HERE] | D21: 0 | E21: =+C21*D21 -> 0 | H21: 0 | I21: =+G21*H21 -> 0 | L21: Labor Category 9: [INSERT LABOR CATEGORY NAME HERE] | N21: 0 | O21: =+M21*N21 -> 0 | R21: 0 | S21: =+Q21*R21 -> 0
B22: Labor Category 10: [INSERT LABOR CATEGORY NAME HERE] | D22: 0 | E22: =+C22*D22 -> 0 | H22: 0 | I22: =+G22*H22 -> 0 | L22: Labor Category 10: [INSERT LABOR CATEGORY NAME HERE] | N22: 0 | O22: =+M22*N22 -> 0 | R22: 0 | S22: =+Q22*R22 -> 0
B23: Labor Category 11: [INSERT LABOR CATEGORY NAME HERE] | D23: 0 | E23: =+C23*D23 -> 0 | H23: 0 | I23: =+G23*H23 -> 0 | L23: Labor Category 11: [INSERT LABOR CATEGORY NAME HERE] | N23: 0 | O23: =+M23*N23 -> 0 | R23: 0 | S23: =+Q23*R23 -> 0
B24: Labor Category 12: [INSERT LABOR CATEGORY NAME HERE] | D24: 0 | E24: =+C24*D24 -> 0 | H24: 0 | I24: =+G24*H24 -> 0 | L24: Labor Category 12: [INSERT LABOR CATEGORY NAME HERE] | N24: 0 | O24: =+M24*N24 -> 0 | R24: 0 | S24: =+Q24*R24 -> 0
B25: Labor Category 13: [INSERT LABOR CATEGORY NAME HERE] | D25: 0 | E25: =+C25*D25 -> 0 | H25: 0 | I25: =+G25*H25 -> 0 | L25: Labor Category 13: [INSERT LABOR CATEGORY NAME HERE] | N25: 0 | O25: =+M25*N25 -> 0 | R25: 0 | S25: =+Q25*R25 -> 0
B26: TOTAL HOURS/COST | C26: =SUM(C13:C25) -> 0 | E26: =SUM(E13:E25) -> 0 | G26: =SUM(G13:G25) -> 0 | I26: =SUM(I13:I25) -> 0 | L26: TOTAL HOURS/COST | M26: =SUM(M13:M25) -> 0 | O26: =SUM(O13:O25) -> 0 | Q26: =SUM(Q13:Q25) -> 0 | S26: =SUM(S13:S25) -> 0
C27: Base | D27: Rates | E27: Cost | G27: Base | H27: Rates | I27: Cost | M27: Base | N27: Rates | O27: Cost | Q27: Base | R27: Rates | S27: Cost
B28: Proposed Add-on Factor (Fringe) | C28: =+E26 -> 0 | D28: 0 | E28: =+C28*D28 -> 0 | G28: =+I26 -> 0 | H28: 0 | I28: =+G28*H28 -> 0 | L28: Proposed Add-on Factor (Fringe) | M28: =+O26 -> 0 | N28: 0 | O28: =+M28*N28 -> 0 | Q28: =+S26 -> 0 | R28: 0 | S28: =+Q28*R28 -> 0
B29: Proposed Add-on Factor (Overhead) | C29: =+C28+E28 -> 0 | D29: 0 | E29: =+C29*D29 -> 0 | G29: =+G28+I28 -> 0 | H29: 0 | I29: =+G29*H29 -> 0 | L29: Proposed Add-on Factor (Overhead) | M29: =+M28+O28 -> 0 | N29: 0 | O29: =+M29*N29 -> 0 | Q29: =+Q28+S28 -> 0 | R29: 0 | S29: =+Q29*R29 -> 0
B30: Proposed Add-on Factor (G&A) | C30: =+C29+E29 -> 0 | D30: 0 | E30: =+C30*D30 -> 0 | G30: =+G29+I29 -> 0 | H30: 0 | I30: =+G30*H30 -> 0 | L30: Proposed Add-on Factor (G&A) | M30: =+M29+O29 -> 0 | N30: 0 | O30: =+M30*N30 -> 0 | Q30: =+Q29+S29 -> 0 | R30: 0 | S30: =+Q30*R30 -> 0
B31: Proposed Add-on Factor (COM) | C31: =+C28 -> 0 | D31: 0 | E31: =+C31*D31 -> 0 | G31: =+G28 -> 0 | H31: 0 | I31: =+G31*H31 -> 0 | L31: Proposed Add-on Factor (COM) | M31: =+M28 -> 0 | N31: 0 | O31: =+M31*N31 -> 0 | Q31: =+Q28 -> 0 | R31: 0 | S31: =+Q31*R31 -> 0
B32: Proposed Add-on Factor (Fee) | C32: =+C30+E30 -> 0 | D32: 0 | E32: =+C32*D32 -> 0 | G32: =+G30+I30 -> 0 | H32: 0 | I32: =+G32*H32 -> 0 | L32: Proposed Add-on Factor (Fee) | M32: =+M30+O30 -> 0 | N32: 0 | O32: =+M32*N32 -> 0 | Q32: =+Q30+S30 -> 0 | R32: 0 | S32: =+Q32*R32 -> 0
B33: Total Proposed Cost | E33: =+SUM(E26,E28,E29,E30) -> 0 | I33: =+SUM(I26,I28,I29,I30) -> 0 | L33: Total Proposed Target Cost | O33: =+SUM(O26,O28,O29,O30) -> 0 | S33: =+SUM(S26,S28,S29,S30) -> 0
B34: Total Proposed COM | E34: =+E31 -> 0 | I34: =+I31 -> 0 | L34: Total Proposed Target COM | O34: =+O31 -> 0 | S34: =+S31 -> 0
B35: Total Proposed Fee | E35: =+E32 -> 0 | I35: =+I32 -> 0 | L35: Total Proposed Target Fee | O35: =+O32 -> 0 | S35: =+S32 -> 0
B36: Total Proposed Price | E36: =SUM(E33:E35) -> 0 | I36: =SUM(I33:I35) -> 0 | L36: Total Proposed Target Price | O36: =SUM(O33:O35) -> 0 | S36: =SUM(S33:S35) -> 0
B39: =B10 -> CLINs 0003 & 1003: CPFF | C39: Proposed Prices (Material) | G39: Proposed Prices (Material) | M39: Proposed Prices (Material) | Q39: Proposed Prices (Material)
C40: =C11 -> 0003: A-10 O-Level Handheld/Pre-load Tester Prototype design and digital development - Basic Period | G40: =G11 -> 1003: A-10 O-Level Handheld/Pre-load Tester EMD - Option Period 1 | M40: =M11 -> 2003: F-16 I-Level Fault Isolation Tester EMD - Option Period 2 | Q40: =Q11 -> 3003: F-15 I-Level Fault Isolation Tester EMD - Option Period 3
C41: Base | D41: Rates | E41: Cost | G41: Base | H41: Rates | I41: Cost | M41: Base | N41: Rates | O41: Cost | Q41: Base | R41: Rates | S41: Cost
B42: Total Proposed Material Cost | L42: Total Proposed Material Cost
B43: Proposed Add-on Factor (Overhead) | C43: =+E42 -> 0 | D43: 0 | E43: =+C43*D43 -> 0 | G43: =+I42 -> 0 | H43: 0 | I43: =+G43*H43 -> 0 | L43: Proposed Add-on Factor (Overhead) | M43: =+O42 -> 0 | N43: 0 | O43: =+M43*N43 -> 0 | Q43: =+S42 -> 0 | R43: 0 | S43: =+Q43*R43 -> 0
B44: Proposed Add-on Factor (G&A) | C44: =+C43+E43 -> 0 | D44: 0 | E44: =+C44*D44 -> 0 | G44: =+G43+I43 -> 0 | H44: 0 | I44: =+G44*H44 -> 0 | L44: Proposed Add-on Factor (G&A) | M44: =+M43+O43 -> 0 | N44: 0 | O44: =+M44*N44 -> 0 | Q44: =+Q43+S43 -> 0 | R44: 0 | S44: =+Q44*R44 -> 0
...

Sheet Cost Format A_CLIN X004
B1: Notes:
B2: 1. The format of this worksheet may be revised as required to be consistent with the major subcontractor's approved accounting system.
B3: 2. The Prime Offeror shall propose labor hours, material costs, and other direct costs in the yellow-highlighted cells below.
B4: 3. The Prime Offeror shall ensure the yellow-highlighted rate cells below are linked correctly from the relevant labor rate and add-on factors in the 'Cost Format B_PRIME Rates' worksheet.
B5: 4. The proposed factors will be applied to the proposed labor hours, material cost, and other direct costs.
B6: 5. Definitions of the labor categories and add-on factors are included in the 'Cost Format B_PRIME Rate Desc' worksheet.
B7: 6. Each CPFF/CPIF Cost, COM and Fee shall be rounded to the nearest whole dollar.
B10: CLINs 0004 & 1004: CPFF | C10: Proposed Prices (Labor) | G10: Proposed Prices (Labor) | L10: CLINs 2004 & 3004: CPIF | M10: Proposed Prices (Labor) | Q10: Proposed Prices (Labor)
C11: 0004: F-16 I-Level Fault Isolation Tester design and digital development - Basic Period | G11: 1004: F-16 I-Level Fault Isolation Tester EMD - Option Period 1 | M11: 2004: F-15 I-Level Fault Isolation Tester EMD - Option Period 2 | Q11: 3004: A-10 I-Level Fault Isolation Tester EMD - Option Period 3
B12: Labor Category | C12: Hours | D12: Rates | E12: Cost | G12: Hours | H12: Rates | I12: Cost | L12: Labor Category | M12: Hours | N12: Rates | O12: Cost | Q12: Hours | R12: Rates | S12: Cost
B13: Labor Category 1: [INSERT LABOR CATEGORY NAME HERE] | D13: 0 | E13: =+C13*D13 -> 0 | H13: 0 | I13: =+G13*H13 -> 0 | L13: Labor Category 1: [INSERT LABOR CATEGORY NAME HERE] | N13: 0 | O13: =+M13*N13 -> 0 | R13: 0 | S13: =+Q13*R13 -> 0
B14: Labor Category 2: [INSERT LABOR CATEGORY NAME HERE] | D14: 0 | E14: =+C14*D14 -> 0 | H14: 0 | I14: =+G14*H14 -> 0 | L14: Labor Category 2: [INSERT LABOR CATEGORY NAME HERE] | N14: 0 | O14: =+M14*N14 -> 0 | R14: 0 | S14: =+Q14*R14 -> 0
B15: Labor Category 3: [INSERT LABOR CATEGORY NAME HERE] | D15: 0 | E15: =+C15*D15 -> 0 | H15: 0 | I15: =+G15*H15 -> 0 | L15: Labor Category 3: [INSERT LABOR CATEGORY NAME HERE] | N15: 0 | O15: =+M15*N15 -> 0 | R15: 0 | S15: =+Q15*R15 -> 0
B16: Labor Category 4: [INSERT LABOR CATEGORY NAME HERE] | D16: 0 | E16: =+C16*D16 -> 0 | H16: 0 | I16: =+G16*H16 -> 0 | L16: Labor Category 4: [INSERT LABOR CATEGORY NAME HERE] | N16: 0 | O16: =+M16*N16 -> 0 | R16: 0 | S16: =+Q16*R16 -> 0
B17: Labor Category 5: [INSERT LABOR CATEGORY NAME HERE] | D17: 0 | E17: =+C17*D17 -> 0 | H17: 0 | I17: =+G17*H17 -> 0 | L17: Labor Category 5: [INSERT LABOR CATEGORY NAME HERE] | N17: 0 | O17: =+M17*N17 -> 0 | R17: 0 | S17: =+Q17*R17 -> 0
B18: Labor Category 6: [INSERT LABOR CATEGORY NAME HERE] | D18: 0 | E18: =+C18*D18 -> 0 | H18: 0 | I18: =+G18*H18 -> 0 | L18: Labor Category 6: [INSERT LABOR CATEGORY NAME HERE] | N18: 0 | O18: =+M18*N18 -> 0 | R18: 0 | S18: =+Q18*R18 -> 0
B19: Labor Category 7: [INSERT LABOR CATEGORY NAME HERE] | D19: 0 | E19: =+C19*D19 -> 0 | H19: 0 | I19: =+G19*H19 -> 0 | L19: Labor Category 7: [INSERT LABOR CATEGORY NAME HERE] | N19: 0 | O19: =+M19*N19 -> 0 | R19: 0 | S19: =+Q19*R19 -> 0
B20: Labor Category 8: [INSERT LABOR CATEGORY NAME HERE] | D20: 0 | E20: =+C20*D20 -> 0 | H20: 0 | I20: =+G20*H20 -> 0 | L20: Labor Category 8: [INSERT LABOR CATEGORY NAME HERE] | N20: 0 | O20: =+M20*N20 -> 0 | R20: 0 | S20: =+Q20*R20 -> 0
B21: Labor Category 9: [INSERT LABOR CATEGORY NAME HERE] | D21: 0 | E21: =+C21*D21 -> 0 | H21: 0 | I21: =+G21*H21 -> 0 | L21: Labor Category 9: [INSERT LABOR CATEGORY NAME HERE] | N21: 0 | O21: =+M21*N21 -> 0 | R21: 0 | S21: =+Q21*R21 -> 0
B22: Labor Category 10: [INSERT LABOR CATEGORY NAME HERE] | D22: 0 | E22: =+C22*D22 -> 0 | H22: 0 | I22: =+G22*H22 -> 0 | L22: Labor Category 10: [INSERT LABOR CATEGORY NAME HERE] | N22: 0 | O22: =+M22*N22 -> 0 | R22: 0 | S22: =+Q22*R22 -> 0
B23: Labor Category 11: [INSERT LABOR CATEGORY NAME HERE] | D23: 0 | E23: =+C23*D23 -> 0 | H23: 0 | I23: =+G23*H23 -> 0 | L23: Labor Category 11: [INSERT LABOR CATEGORY NAME HERE] | N23: 0 | O23: =+M23*N23 -> 0 | R23: 0 | S23: =+Q23*R23 -> 0
B24: Labor Category 12: [INSERT LABOR CATEGORY NAME HERE] | D24: 0 | E24: =+C24*D24 -> 0 | H24: 0 | I24: =+G24*H24 -> 0 | L24: Labor Category 12: [INSERT LABOR CATEGORY NAME HERE] | N24: 0 | O24: =+M24*N24 -> 0 | R24: 0 | S24: =+Q24*R24 -> 0
B25: Labor Category 13: [INSERT LABOR CATEGORY NAME HERE] | D25: 0 | E25: =+C25*D25 -> 0 | H25: 0 | I25: =+G25*H25 -> 0 | L25: Labor Category 13: [INSERT LABOR CATEGORY NAME HERE] | N25: 0 | O25: =+M25*N25 -> 0 | R25: 0 | S25: =+Q25*R25 -> 0
B26: TOTAL HOURS/COST | C26: =SUM(C13:C25) -> 0 | E26: =SUM(E13:E25) -> 0 | G26: =SUM(G13:G25) -> 0 | I26: =SUM(I13:I25) -> 0 | L26: TOTAL HOURS/COST | M26: =SUM(M13:M25) -> 0 | O26: =SUM(O13:O25) -> 0 | Q26: =SUM(Q13:Q25) -> 0 | S26: =SUM(S13:S25) -> 0
C27: Base | D27: Rates | E27: Cost | G27: Base | H27: Rates | I27: Cost | M27: Base | N27: Rates | O27: Cost | Q27: Base | R27: Rates | S27: Cost
B28: Proposed Add-on Factor (Fringe) | C28: =+E26 -> 0 | D28: 0 | E28: =+C28*D28 -> 0 | G28: =+I26 -> 0 | H28: 0 | I28: =+G28*H28 -> 0 | L28: Proposed Add-on Factor (Fringe) | M28: =+O26 -> 0 | N28: 0 | O28: =+M28*N28 -> 0 | Q28: =+S26 -> 0 | R28: 0 | S28: =+Q28*R28 -> 0
B29: Proposed Add-on Factor (Overhead) | C29: =+C28+E28 -> 0 | D29: 0 | E29: =+C29*D29 -> 0 | G29: =+G28+I28 -> 0 | H29: 0 | I29: =+G29*H29 -> 0 | L29: Proposed Add-on Factor (Overhead) | M29: =+M28+O28 -> 0 | N29: 0 | O29: =+M29*N29 -> 0 | Q29: =+Q28+S28 -> 0 | R29: 0 | S29: =+Q29*R29 -> 0
B30: Proposed Add-on Factor (G&A) | C30: =+C29+E29 -> 0 | D30: 0 | E30: =+C30*D30 -> 0 | G30: =+G29+I29 -> 0 | H30: 0 | I30: =+G30*H30 -> 0 | L30: Proposed Add-on Factor (G&A) | M30: =+M29+O29 -> 0 | N30: 0 | O30: =+M30*N30 -> 0 | Q30: =+Q29+S29 -> 0 | R30: 0 | S30: =+Q30*R30 -> 0
B31: Proposed Add-on Factor (COM) | C31: =+C28 -> 0 | D31: 0 | E31: =+C31*D31 -> 0 | G31: =+G28 -> 0 | H31: 0 | I31: =+G31*H31 -> 0 | L31: Proposed Add-on Factor (COM) | M31: =+M28 -> 0 | N31: 0 | O31: =+M31*N31 -> 0 | Q31: =+Q28 -> 0 | R31: 0 | S31: =+Q31*R31 -> 0
B32: Proposed Add-on Factor (Fee) | C32: =+C30+E30 -> 0 | D32: 0 | E32: =+C32*D32 -> 0 | G32: =+G30+I30 -> 0 | H32: 0 | I32: =+G32*H32 -> 0 | L32: Proposed Add-on Factor (Fee) | M32: =+M30+O30 -> 0 | N32: 0 | O32: =+M32*N32 -> 0 | Q32: =+Q30+S30 -> 0 | R32: 0 | S32: =+Q32*R32 -> 0
B33: Total Proposed Cost | E33: =+SUM(E26,E28,E29,E30) -> 0 | I33: =+SUM(I26,I28,I29,I30) -> 0 | L33: Total Proposed Target Cost | O33: =+SUM(O26,O28,O29,O30) -> 0 | S33: =+SUM(S26,S28,S29,S30) -> 0
B34: Total Proposed COM | E34: =+E31 -> 0 | I34: =+I31 -> 0 | L34: Total Proposed Target COM | O34: =+O31 -> 0 | S34: =+S31 -> 0
B35: Total Proposed Fee | E35: =+E32 -> 0 | I35: =+I32 -> 0 | L35: Total Proposed Target Fee | O35: =+O32 -> 0 | S35: =+S32 -> 0
B36: Total Proposed Price | E36: =SUM(E33:E35) -> 0 | I36: =SUM(I33:I35) -> 0 | L36: Total Proposed Target Price | O36: =SUM(O33:O35) -> 0 | S36: =SUM(S33:S35) -> 0
B39: =B10 -> CLINs 0004 & 1004: CPFF | C39: Proposed Prices (Material) | G39: Proposed Prices (Material) | M39: Proposed Prices (Material) | Q39: Proposed Prices (Material)
C40: =C11 -> 0004: F-16 I-Level Fault Isolation Tester design and digital development - Basic Period | G40: =G11 -> 1004: F-16 I-Level Fault Isolation Tester EMD - Option Period 1 | M40: =M11 -> 2004: F-15 I-Level Fault Isolation Tester EMD - Option Period 2 | Q40: =Q11 -> 3004: A-10 I-Level Fault Isolation Tester EMD - Option Period 3
C41: Base | D41: Rates | E41: Cost | G41: Base | H41: Rates | I41: Cost | M41: Base | N41: Rates | O41: Cost | Q41: Base | R41: Rates | S41: Cost
B42: Total Proposed Material Cost | L42: Total Proposed Material Cost
B43: Proposed Add-on Factor (Overhead) | C43: =+E42 -> 0 | D43: 0 | E43: =+C43*D43 -> 0 | G43: =+I42 -> 0 | H43: 0 | I43: =+G43*H43 -> 0 | L43: Proposed Add-on Factor (Overhead) | M43: =+O42 -> 0 | N43: 0 | O43: =+M43*N43 -> 0 | Q43: =+S42 -> 0 | R43: 0 | S43: =+Q43*R43 -> 0
B44: Proposed Add-on Factor (G&A) | C44: =+C43+E43 -> 0 | D44: 0 | E44: =+C44*D44 -> 0 | G44: =+G43+I43 -> 0 | H44: 0 | I44: =+G44*H44 -> 0 | L44: Proposed Add-on Factor (G&A) | M44: =+M43+O43 -> 0 | N44: 0 | O44: =+M44*N44 -> 0 | Q44: =+Q43+S43 -> 0 | R44: 0 | S44: =+Q44*R44 -> 0
...

Sheet Cost Format A_CLIN X005
B1: Notes:
B2: 1. The format of this worksheet may be revised as required to be consistent with the major subcontractor's approved accounting system.
B3: 2. The Prime Offeror shall propose labor hours, material costs, and other direct costs in the yellow-highlighted cells below.
B4: 3. The Prime Offeror shall ensure the yellow-highlighted rate cells below are linked correctly from the relevant labor rate and add-on factors in the 'Cost Format B_PRIME Rates' worksheet.
B5: 4. The proposed factors will be applied to the proposed labor hours, material cost, and other direct costs.
B6: 5. Definitions of the labor categories and add-on factors are included in the 'Cost Format B_PRIME Rate Desc' worksheet.
B7: 6. Each CPFF/CPIF Cost, COM and Fee shall be rounded to the nearest whole dollar.
B10: CLINs 0005 & 1005: CPFF | C10: Proposed Prices (Labor) | G10: Proposed Prices (Labor) | L10: CLIN 2005: CPIF | M10: Proposed Prices (Labor)
C11: 0005: F-15 I-Level Fault Isolation Tester design and digital development - Basic Period | G11: 1005: F-15 I-Level Fault Isolation Tester EMD - Option Period 1 | M11: 2005: A-10 I-Level Fault Isolation Tester EMD - Option Period 2
B12: Labor Category | C12: Hours | D12: Rates | E12: Cost | G12: Hours | H12: Rates | I12: Cost | L12: Labor Category | M12: Hours | N12: Rates | O12: Cost
B13: Labor Category 1: [INSERT LABOR CATEGORY NAME HERE] | D13: 0 | E13: =+C13*D13 -> 0 | H13: 0 | I13: =+G13*H13 -> 0 | L13: Labor Category 1: [INSERT LABOR CATEGORY NAME HERE] | N13: 0 | O13: =+M13*N13 -> 0
B14: Labor Category 2: [INSERT LABOR CATEGORY NAME HERE] | D14: 0 | E14: =+C14*D14 -> 0 | H14: 0 | I14: =+G14*H14 -> 0 | L14: Labor Category 2: [INSERT LABOR CATEGORY NAME HERE] | N14: 0 | O14: =+M14*N14 -> 0
B15: Labor Category 3: [INSERT LABOR CATEGORY NAME HERE] | D15: 0 | E15: =+C15*D15 -> 0 | H15: 0 | I15: =+G15*H15 -> 0 | L15: Labor Category 3: [INSERT LABOR CATEGORY NAME HERE] | N15: 0 | O15: =+M15*N15 -> 0
B16: Labor Category 4: [INSERT LABOR CATEGORY NAME HERE] | D16: 0 | E16: =+C16*D16 -> 0 | H16: 0 | I16: =+G16*H16 -> 0 | L16: Labor Category 4: [INSERT LABOR CATEGORY NAME HERE] | N16: 0 | O16: =+M16*N16 -> 0
B17: Labor Category 5: [INSERT LABOR CATEGORY NAME HERE] | D17: 0 | E17: =+C17*D17 -> 0 | H17: 0 | I17: =+G17*H17 -> 0 | L17: Labor Category 5: [INSERT LABOR CATEGORY NAME HERE] | N17: 0 | O17: =+M17*N17 -> 0
B18: Labor Category 6: [INSERT LABOR CATEGORY NAME HERE] | D18: 0 | E18: =+C18*D18 -> 0 | H18: 0 | I18: =+G18*H18 -> 0 | L18: Labor Category 6: [INSERT LABOR CATEGORY NAME HERE] | N18: 0 | O18: =+M18*N18 -> 0
B19: Labor Category 7: [INSERT LABOR CATEGORY NAME HERE] | D19: 0 | E19: =+C19*D19 -> 0 | H19: 0 | I19: =+G19*H19 -> 0 | L19: Labor Category 7: [INSERT LABOR CATEGORY NAME HERE] | N19: 0 | O19: =+M19*N19 -> 0
B20: Labor Category 8: [INSERT LABOR CATEGORY NAME HERE] | D20: 0 | E20: =+C20*D20 -> 0 | H20: 0 | I20: =+G20*H20 -> 0 | L20: Labor Category 8: [INSERT LABOR CATEGORY NAME HERE] | N20: 0 | O20: =+M20*N20 -> 0
B21: Labor Category 9: [INSERT LABOR CATEGORY NAME HERE] | D21: 0 | E21: =+C21*D21 -> 0 | H21: 0 | I21: =+G21*H21 -> 0 | L21: Labor Category 9: [INSERT LABOR CATEGORY NAME HERE] | N21: 0 | O21: =+M21*N21 -> 0
B22: Labor Category 10: [INSERT LABOR CATEGORY NAME HERE] | D22: 0 | E22: =+C22*D22 -> 0 | H22: 0 | I22: =+G22*H22 -> 0 | L22: Labor Category 10: [INSERT LABOR CATEGORY NAME HERE] | N22: 0 | O22: =+M22*N22 -> 0
B23: Labor Category 11: [INSERT LABOR CATEGORY NAME HERE] | D23: 0 | E23: =+C23*D23 -> 0 | H23: 0 | I23: =+G23*H23 -> 0 | L23: Labor Category 11: [INSERT LABOR CATEGORY NAME HERE] | N23: 0 | O23: =+M23*N23 -> 0
B24: Labor Category 12: [INSERT LABOR CATEGORY NAME HERE] | D24: 0 | E24: =+C24*D24 -> 0 | H24: 0 | I24: =+G24*H24 -> 0 | L24: Labor Category 12: [INSERT LABOR CATEGORY NAME HERE] | N24: 0 | O24: =+M24*N24 -> 0
B25: Labor Category 13: [INSERT LABOR CATEGORY NAME HERE] | D25: 0 | E25: =+C25*D25 -> 0 | H25: 0 | I25: =+G25*H25 -> 0 | L25: Labor Category 13: [INSERT LABOR CATEGORY NAME HERE] | N25: 0 | O25: =+M25*N25 -> 0
B26: TOTAL HOURS/COST | C26: =SUM(C13:C25) -> 0 | E26: =SUM(E13:E25) -> 0 | G26: =SUM(G13:G25) -> 0 | I26: =SUM(I13:I25) -> 0 | L26: TOTAL HOURS/COST | M26: =SUM(M13:M25) -> 0 | O26: =SUM(O13:O25) -> 0
C27: Base | D27: Rates | E27: Cost | G27: Base | H27: Rates | I27: Cost | M27: Base | N27: Rates | O27: Cost
B28: Proposed Add-on Factor (Fringe) | C28: =+E26 -> 0 | D28: 0 | E28: =+C28*D28 -> 0 | G28: =+I26 -> 0 | H28: 0 | I28: =+G28*H28 -> 0 | L28: Proposed Add-on Factor (Fringe) | M28: =+O26 -> 0 | N28: 0 | O28: =+M28*N28 -> 0
B29: Proposed Add-on Factor (Overhead) | C29: =+C28+E28 -> 0 | D29: 0 | E29: =+C29*D29 -> 0 | G29: =+G28+I28 -> 0 | H29: 0 | I29: =+G29*H29 -> 0 | L29: Proposed Add-on Factor (Overhead) | M29: =+M28+O28 -> 0 | N29: 0 | O29: =+M29*N29 -> 0
B30: Proposed Add-on Factor (G&A) | C30: =+C29+E29 -> 0 | D30: 0 | E30: =+C30*D30 -> 0 | G30: =+G29+I29 -> 0 | H30: 0 | I30: =+G30*H30 -> 0 | L30: Proposed Add-on Factor (G&A) | M30: =+M29+O29 -> 0 | N30: 0 | O30: =+M30*N30 -> 0
B31: Proposed Add-on Factor (COM) | C31: =+C28 -> 0 | D31: 0 | E31: =+C31*D31 -> 0 | G31: =+G28 -> 0 | H31: 0 | I31: =+G31*H31 -> 0 | L31: Proposed Add-on Factor (COM) | M31: =+M28 -> 0 | N31: 0 | O31: =+M31*N31 -> 0
B32: Proposed Add-on Factor (Fee) | C32: =+C30+E30 -> 0 | D32: 0 | E32: =+C32*D32 -> 0 | G32: =+G30+I30 -> 0 | H32: 0 | I32: =+G32*H32 -> 0 | L32: Proposed Add-on Factor (Fee) | M32: =+M30+O30 -> 0 | N32: 0 | O32: =+M32*N32 -> 0
B33: Total Proposed Cost | E33: =+SUM(E26,E28,E29,E30) -> 0 | I33: =+SUM(I26,I28,I29,I30) -> 0 | L33: Total Proposed Target Cost | O33: =+SUM(O26,O28,O29,O30) -> 0
B34: Total Proposed COM | E34: =+E31 -> 0 | I34: =+I31 -> 0 | L34: Total Proposed Target COM | O34: =+O31 -> 0
B35: Total Proposed Fee | E35: =+E32 -> 0 | I35: =+I32 -> 0 | L35: Total Proposed Target Fee | O35: =+O32 -> 0
B36: Total Proposed Price | E36: =SUM(E33:E35) -> 0 | I36: =SUM(I33:I35) -> 0 | L36: Total Proposed Target Price | O36: =SUM(O33:O35) -> 0
B39: =B10 -> CLINs 0005 & 1005: CPFF | C39: Proposed Prices (Material) | G39: Proposed Prices (Material) | M39: Proposed Prices (Material)
C40: =C11 -> 0005: F-15 I-Level Fault Isolation Tester design and digital development - Basic Period | G40: =G11 -> 1005: F-15 I-Level Fault Isolation Tester EMD - Option Period 1 | M40: =M11 -> 2005: A-10 I-Level Fault Isolation Tester EMD - Option Period 2
C41: Base | D41: Rates | E41: Cost | G41: Base | H41: Rates | I41: Cost | M41: Base | N41: Rates | O41: Cost
B42: Total Proposed Material Cost | L42: Total Proposed Material Cost
B43: Proposed Add-on Factor (Overhead) | C43: =+E42 -> 0 | D43: 0 | E43: =+C43*D43 -> 0 | G43: =+I42 -> 0 | H43: 0 | I43: =+G43*H43 -> 0 | L43: Proposed Add-on Factor (Overhead) | M43: =+O42 -> 0 | N43: 0 | O43: =+M43*N43 -> 0
B44: Proposed Add-on Factor (G&A) | C44: =+C43+E43 -> 0 | D44: 0 | E44: =+C44*D44 -> 0 | G44: =+G43+I43 -> 0 | H44: 0 | I44: =+G44*H44 -> 0 | L44: Proposed Add-on Factor (G&A) | M44: =+M43+O43 -> 0 | N44: 0 | O44: =+M44*N44 -> 0
...

Sheet Cost Format A_CLIN X006
B1: Notes:
B2: 1. The format of this worksheet may be revised as required to be consistent with the major subcontractor's approved accounting system.
B3: 2. The Prime Offeror shall propose labor hours, material costs, and other direct costs in the yellow-highlighted cells below.
B4: 3. The Prime Offeror shall ensure the yellow-highlighted rate cells below are linked correctly from the relevant labor rate and add-on factors in the 'Cost Format B_PRIME Rates' worksheet.
B5: 4. The proposed factors will be applied to the proposed labor hours, material cost, and other direct costs.
B6: 5. Definitions of the labor categories and add-on factors are included in the 'Cost Format B_PRIME Rate Desc' worksheet.
B7: 6. Each CPFF/CPIF Cost, COM and Fee shall be rounded to the nearest whole dollar.
B10: CLINs 0006 & 1006: CPFF | C10: Proposed Prices (Labor) | G10: Proposed Prices (Labor)
C11: 0006: A-10 I-Level Fault Isolation Tester design and digital development - Basic Period | G11: 1006: A-10 I-Level Fault Isolation Tester EMD - Option Period 1
B12: Labor Category | C12: Hours | D12: Rates | E12: Cost | G12: Hours | H12: Rates | I12: Cost
B13: Labor Category 1: [INSERT LABOR CATEGORY NAME HERE] | D13: 0 | E13: =+C13*D13 -> 0 | H13: 0 | I13: =+G13*H13 -> 0
B14: Labor Category 2: [INSERT LABOR CATEGORY NAME HERE] | D14: 0 | E14: =+C14*D14 -> 0 | H14: 0 | I14: =+G14*H14 -> 0
B15: Labor Category 3: [INSERT LABOR CATEGORY NAME HERE] | D15: 0 | E15: =+C15*D15 -> 0 | H15: 0 | I15: =+G15*H15 -> 0
B16: Labor Category 4: [INSERT LABOR CATEGORY NAME HERE] | D16: 0 | E16: =+C16*D16 -> 0 | H16: 0 | I16: =+G16*H16 -> 0
B17: Labor Category 5: [INSERT LABOR CATEGORY NAME HERE] | D17: 0 | E17: =+C17*D17 -> 0 | H17: 0 | I17: =+G17*H17 -> 0
B18: Labor Category 6: [INSERT LABOR CATEGORY NAME HERE] | D18: 0 | E18: =+C18*D18 -> 0 | H18: 0 | I18: =+G18*H18 -> 0
B19: Labor Category 7: [INSERT LABOR CATEGORY NAME HERE] | D19: 0 | E19: =+C19*D19 -> 0 | H19: 0 | I19: =+G19*H19 -> 0
B20: Labor Category 8: [INSERT LABOR CATEGORY NAME HERE] | D20: 0 | E20: =+C20*D20 -> 0 | H20: 0 | I20: =+G20*H20 -> 0
B21: Labor Category 9: [INSERT LABOR CATEGORY NAME HERE] | D21: 0 | E21: =+C21*D21 -> 0 | H21: 0 | I21: =+G21*H21 -> 0
B22: Labor Category 10: [INSERT LABOR CATEGORY NAME HERE] | D22: 0 | E22: =+C22*D22 -> 0 | H22: 0 | I22: =+G22*H22 -> 0
B23: Labor Category 11: [INSERT LABOR CATEGORY NAME HERE] | D23: 0 | E23: =+C23*D23 -> 0 | H23: 0 | I23: =+G23*H23 -> 0
B24: Labor Category 12: [INSERT LABOR CATEGORY NAME HERE] | D24: 0 | E24: =+C24*D24 -> 0 | H24: 0 | I24: =+G24*H24 -> 0
B25: Labor Category 13: [INSERT LABOR CATEGORY NAME HERE] | D25: 0 | E25: =+C25*D25 -> 0 | H25: 0 | I25: =+G25*H25 -> 0
B26: TOTAL HOURS/COST | C26: =SUM(C13:C25) -> 0 | E26: =SUM(E13:E25) -> 0 | G26: =SUM(G13:G25) -> 0 | I26: =SUM(I13:I25) -> 0
C27: Base | D27: Rates | E27: Cost | G27: Base | H27: Rates | I27: Cost
B28: Proposed Add-on Factor (Fringe) | C28: =+E26 -> 0 | D28: 0 | E28: =+C28*D28 -> 0 | G28: =+I26 -> 0 | H28: 0 | I28: =+G28*H28 -> 0
B29: Proposed Add-on Factor (Overhead) | C29: =+C28+E28 -> 0 | D29: 0 | E29: =+C29*D29 -> 0 | G29: =+G28+I28 -> 0 | H29: 0 | I29: =+G29*H29 -> 0
B30: Proposed Add-on Factor (G&A) | C30: =+C29+E29 -> 0 | D30: 0 | E30: =+C30*D30 -> 0 | G30: =+G29+I29 -> 0 | H30: 0 | I30: =+G30*H30 -> 0
B31: Proposed Add-on Factor (COM) | C31: =+C28 -> 0 | D31: 0 | E31: =+C31*D31 -> 0 | G31: =+G28 -> 0 | H31: 0 | I31: =+G31*H31 -> 0
B32: Proposed Add-on Factor (Fee) | C32: =+C30+E30 -> 0 | D32: 0 | E32: =+C32*D32 -> 0 | G32: =+G30+I30 -> 0 | H32: 0 | I32: =+G32*H32 -> 0
B33: Total Proposed Cost | E33: =+SUM(E26,E28,E29,E30) -> 0 | I33: =+SUM(I26,I28,I29,I30) -> 0
B34: Total Proposed COM | E34: =+E31 -> 0 | I34: =+I31 -> 0
